Workbook
Name A: [1]ISR!#REF!
Name A: [1]ISR!#REF!
Name AS: [1]ISR!#REF!
Name AS: [1]ISR!#REF!
Name B: [2]ISR!#REF!
Name B: [2]ISR!#REF!
Name CREDITOS: [1]ISR!#REF!
Name CREDITOS: [1]ISR!#REF!
Name CREDITOS: [1]ISR!#REF!
Name CREDITOS: [1]ISR!#REF!
Name CREDITOS02: [1]CREDITOS!#REF!
Name CREDITOS02: [1]CREDITOS!#REF!
Name CREDITOS02: [1]CREDITOS!#REF!
Name CREDITOS02: [1]CREDITOS!#REF!
Name CREDITOSIMPAC: [1]ISR!#REF!
Name CREDITOSIMPAC: [1]ISR!#REF!
Name CREDITOSIMPAC: [1]ISR!#REF!
Name CREDITOSIMPAC: [1]ISR!#REF!
Name D: [1]ISR!#REF!
Name D: [1]ISR!#REF!
Name DEUDAS: [1]ISR!#REF!
Name DEUDAS: [1]ISR!#REF!
Name DEUDAS: [1]ISR!#REF!
Name DEUDAS: [1]ISR!#REF!
Name DISEÑO: [1]ISR!#REF!
Name DISEÑO: [1]ISR!#REF!
Name DISEÑO: [1]ISR!#REF!
Name DISEÑO: [1]ISR!#REF!
Name E: [1]ISR!#REF!
Name E: [1]ISR!#REF!
Name HOJA: [1]ISR!#REF!
Name HOJA: [1]ISR!#REF!
Name HOJA: [1]ISR!#REF!
Name HOJA1: [1]CREDITOS!#REF!
Name HOJA1: [1]CREDITOS!#REF!
Name HOJA1: [1]CREDITOS!#REF!
Name INTERESES: [2]ISR!#REF!
Name INTERESES: [2]ISR!#REF!
Name INTERESES: [2]ISR!#REF!
Name INTERESES: [2]ISR!#REF!
Name OTROS_DATOS: #REF!
Name OTROS_DATOS: #REF!
Name OTROS_DATOS: #REF!
Name OTROS_DATOS: #REF!
Name RESUMEN_IMPAC: #REF!
Name RESUMEN_IMPAC: #REF!
Name RESUMEN_IMPAC: #REF!
Name RESUMEN_IMPAC: #REF!

Sheet TABLAS
A2: TARIFA ACTUALIZADA DEL IMPUESTO CORRESPONDIENTE AL EJERCICIO DE 2026
A3: TARIFA PARA EL CALCULO DEL EJERCICIO 2026
G4: BASE GRAVABLE | H4: 10000
A5: TARIFA MENSUAL 2026 | F5: (-) | G5: LIMITE INFERIOR | H5: =+VLOOKUP(H4,$A$7:$D$17,1) -> 7168.52
A6: LIMITE INFERIOR | B6: LIMITE SUPERIOR | C6: CUOTA FIJA | D6: % EXC. LIMITE INF. | G6: EXED. S/LIM. INFERIOR | H6: =+H4-H5 -> 2831.48
A7: 0.01 | B7: 844.59 | C7: 0 | D7: 0.0192 | F7: (x) | G7: % S/EXED. LIM. INF. | H7: =+VLOOKUP(H4,$A$7:$D$17,4) -> 0.1088
A8: 844.6 | B8: 7168.51 | C8: 16.22 | D8: 0.064 | G8: IMPUESTO MARGINAL | H8: =H6*H7 -> 308.06502
A9: 7168.52 | B9: 12598.02 | C9: 420.95 | D9: 0.1088 | F9: (+) | G9: CUOTA FIJA | H9: =+VLOOKUP(H4,$A$7:$D$17,3) -> 420.95
A10: 12598.03 | B10: 14644.64 | C10: 1011.68 | D10: 0.16 | G10: IMPUESTO CAUSADO 113 | H10: =+H8+H9 -> 729.01502
A11: 14644.65 | B11: 17533.64 | C11: 1339.14 | D11: 0.1792 | F11: (-) | G11: SUBSIDIO PARA EL EMPLEO | H11: 0
A12: 17533.65 | B12: 35362.83 | C12: 1856.84 | D12: 0.2136 | G12: IMPUESTO A RETENER | H12: =+H10-H11 -> 729.01502
A13: 35362.84 | B13: 55736.68 | C13: 5665.16 | D13: 0.2352
A14: 55736.69 | B14: 106410.5 | C14: 10457.09 | D14: 0.3
A15: 106410.51 | B15: 141880.66 | C15: 25659.23 | D15: 0.32
A16: 141880.67 | B16: 425641.99 | C16: 37009.69 | D16: 0.34
A17: 425642 | B17: EN ADELANTE | C17: 133488.54 | D17: 0.35
A28: 1.00 Salario mínimo (SM) | B28: 0 | C28: 248.93 | D28: 0.0315
A29: 1.01 SM a 1.50 UMA | B29: 113.14 | C29: =+B29*1.5 -> 169.71 | D29: 0.03544
A30: 1.51 a 2.00 UMA | B30: =+C29+0.01 -> 169.72 | C30: =+B29*2 -> 226.28 | D30: 0.04426
A31: 2.01 a 2.50 UMA | B31: =+C30+0.01 -> 226.29 | C31: =+B29*2.5 -> 282.85 | D31: 0.04954
A32: 2.51 a 3.00 UMA | B32: =+C31+0.01 -> 282.86 | C32: =+B29*3 -> 339.42 | D32: 0.05307
A33: 3.01 a 3.50 UMA | B33: =+C32+0.01 -> 339.43 | C33: =+B29*3.5 -> 395.99 | D33: 0.05559
A34: 3.51 a 4.00 UMA | B34: =+C33+0.01 -> 396 | C34: =+B29*4 -> 452.56 | D34: 0.05747
A35: 4.01 UMA en adelante | B35: =+C34+0.01 -> 452.57 | C35: 10000 | D35: 0.06422

Sheet NOMINA
A2: NOMINA GENERAL
M3: =TODAY() -> 46085
A5: N° | B5: NOMBRE | C5: CLAVE | D5: TOTAL DEPOSITO | E5: DIAS | F5: SALARIO DIARIO | G5: SUELDO | H5: ART 96 | I5: SUBSIDIO | J5: SUBSIDIO AL EMPLEO | K5: ISR | L5: SUELDO NETO | M5: PPS / IRT | N5: COSTO SOCIAL
A7: 1 | B7: Empleado 1 | C7: Emp 001 | E7: 30 | G7: =E7*F7 -> 0 | H7: =(G7-VLOOKUP(G7,TABLAS!$A$7:$D$17,1))*VLOOKUP(G7,TABLAS!$A$7:$D$17,4)+VLOOKUP(G7,TABLAS!$A$7:$D$17,3) -> #N/A | I7: =IF(G7<=11492.66,(113.14*30.4)*15.02%,0) -> 516.60629 | J7: 0 | K7: =+IF(H7>I7,H7-I7,0) -> #N/A | L7: =+G7-K7 -> #N/A | M7: =+IF(K7>0,(D7-G7+K7),D7-L7) -> #N/A | N7: =IMSS!AK8 -> #N/A | O7: =D7*40% -> 0 | P7: =O7/30 -> 0 | Q7: =IF(P7<472.56,472.56,P7) -> 472.56
A8: =A7+1 -> 2 | B8: Empleado 2 | C8: Emp 002 | E8: 30 | G8: =E8*F8 -> 0 | H8: =(G8-VLOOKUP(G8,TABLAS!$A$7:$D$17,1))*VLOOKUP(G8,TABLAS!$A$7:$D$17,4)+VLOOKUP(G8,TABLAS!$A$7:$D$17,3) -> #N/A | I8: =IF(G8<=11492.66,(113.14*30.4)*15.02%,0) -> 516.60629 | J8: 0 | K8: =+IF(H8>I8,H8-I8,0) -> #N/A | L8: =+G8-K8 -> #N/A | M8: =+IF(K8>0,(D8-G8+K8),D8-L8) -> #N/A | N8: =IMSS!AK9 -> #N/A | O8: =D8*40% -> 0 | P8: =O8/30 -> 0 | Q8: =IF(P8<472.56,472.56,P8) -> 472.56
A9: =A8+1 -> 3 | B9: Empleado 3 | C9: Emp 003 | E9: 30 | G9: =E9*F9 -> 0 | H9: =(G9-VLOOKUP(G9,TABLAS!$A$7:$D$17,1))*VLOOKUP(G9,TABLAS!$A$7:$D$17,4)+VLOOKUP(G9,TABLAS!$A$7:$D$17,3) -> #N/A | I9: =IF(G9<=11492.66,(113.14*30.4)*15.02%,0) -> 516.60629 | J9: 0 | K9: =+IF(H9>I9,H9-I9,0) -> #N/A | L9: =+G9-K9 -> #N/A | M9: =+IF(K9>0,(D9-G9+K9),D9-L9) -> #N/A | N9: =IMSS!AK10 -> #N/A | O9: =D9*40% -> 0 | P9: =O9/30 -> 0 | Q9: =IF(P9<472.56,472.56,P9) -> 472.56
A10: =A9+1 -> 4 | B10: Empleado 4 | C10: Emp 004 | E10: 30 | G10: =E10*F10 -> 0 | H10: =(G10-VLOOKUP(G10,TABLAS!$A$7:$D$17,1))*VLOOKUP(G10,TABLAS!$A$7:$D$17,4)+VLOOKUP(G10,TABLAS!$A$7:$D$17,3) -> #N/A | I10: =IF(G10<=11492.66,(113.14*30.4)*15.02%,0) -> 516.60629 | J10: 0 | K10: =+IF(H10>I10,H10-I10,0) -> #N/A | L10: =+G10-K10 -> #N/A | M10: =+IF(K10>0,(D10-G10+K10),D10-L10) -> #N/A | N10: =IMSS!AK11 -> #N/A | O10: =D10*40% -> 0 | P10: =O10/30 -> 0 | Q10: =IF(P10<472.56,472.56,P10) -> 472.56
A11: =A10+1 -> 5 | B11: Empleado 5 | C11: Emp 005 | E11: 30 | G11: =E11*F11 -> 0 | H11: =(G11-VLOOKUP(G11,TABLAS!$A$7:$D$17,1))*VLOOKUP(G11,TABLAS!$A$7:$D$17,4)+VLOOKUP(G11,TABLAS!$A$7:$D$17,3) -> #N/A | I11: =IF(G11<=11492.66,(113.14*30.4)*15.02%,0) -> 516.60629 | J11: 0 | K11: =+IF(H11>I11,H11-I11,0) -> #N/A | L11: =+G11-K11 -> #N/A | M11: =+IF(K11>0,(D11-G11+K11),D11-L11) -> #N/A | N11: =IMSS!AK12 -> #N/A | O11: =D11*40% -> 0 | P11: =O11/30 -> 0 | Q11: =IF(P11<472.56,472.56,P11) -> 472.56
A12: =A11+1 -> 6 | B12: Empleado 6 | C12: Emp 006 | E12: 30 | G12: =E12*F12 -> 0 | H12: =(G12-VLOOKUP(G12,TABLAS!$A$7:$D$17,1))*VLOOKUP(G12,TABLAS!$A$7:$D$17,4)+VLOOKUP(G12,TABLAS!$A$7:$D$17,3) -> #N/A | I12: =IF(G12<=11492.66,(113.14*30.4)*15.02%,0) -> 516.60629 | J12: 0 | K12: =+IF(H12>I12,H12-I12,0) -> #N/A | L12: =+G12-K12 -> #N/A | M12: =+IF(K12>0,(D12-G12+K12),D12-L12) -> #N/A | N12: =IMSS!AK13 -> #N/A | O12: =D12*40% -> 0 | P12: =O12/30 -> 0 | Q12: =IF(P12<472.56,472.56,P12) -> 472.56
A13: =A12+1 -> 7 | B13: Empleado 7 | C13: Emp 007 | E13: 30 | G13: =E13*F13 -> 0 | H13: =(G13-VLOOKUP(G13,TABLAS!$A$7:$D$17,1))*VLOOKUP(G13,TABLAS!$A$7:$D$17,4)+VLOOKUP(G13,TABLAS!$A$7:$D$17,3) -> #N/A | I13: =IF(G13<=11492.66,(113.14*30.4)*15.02%,0) -> 516.60629 | J13: 0 | K13: =+IF(H13>I13,H13-I13,0) -> #N/A | L13: =+G13-K13 -> #N/A | M13: =+IF(K13>0,(D13-G13+K13),D13-L13) -> #N/A | N13: =IMSS!AK14 -> #N/A | O13: =D13*40% -> 0 | P13: =O13/30 -> 0 | Q13: =IF(P13<472.56,472.56,P13) -> 472.56
A14: =A13+1 -> 8 | B14: Empleado 8 | C14: Emp 008 | E14: 30 | G14: =E14*F14 -> 0 | H14: =(G14-VLOOKUP(G14,TABLAS!$A$7:$D$17,1))*VLOOKUP(G14,TABLAS!$A$7:$D$17,4)+VLOOKUP(G14,TABLAS!$A$7:$D$17,3) -> #N/A | I14: =IF(G14<=11492.66,(113.14*30.4)*15.02%,0) -> 516.60629 | J14: 0 | K14: =+IF(H14>I14,H14-I14,0) -> #N/A | L14: =+G14-K14 -> #N/A | M14: =+IF(K14>0,(D14-G14+K14),D14-L14) -> #N/A | N14: =IMSS!AK15 -> #N/A | O14: =D14*40% -> 0 | P14: =O14/30 -> 0 | Q14: =IF(P14<472.56,472.56,P14) -> 472.56
A15: =A14+1 -> 9 | B15: Empleado 9 | C15: Emp 009 | E15: 30 | G15: =E15*F15 -> 0 | H15: =(G15-VLOOKUP(G15,TABLAS!$A$7:$D$17,1))*VLOOKUP(G15,TABLAS!$A$7:$D$17,4)+VLOOKUP(G15,TABLAS!$A$7:$D$17,3) -> #N/A | I15: =IF(G15<=11492.66,(113.14*30.4)*15.02%,0) -> 516.60629 | J15: 0 | K15: =+IF(H15>I15,H15-I15,0) -> #N/A | L15: =+G15-K15 -> #N/A | M15: =+IF(K15>0,(D15-G15+K15),D15-L15) -> #N/A | N15: =IMSS!AK16 -> #N/A | O15: =D15*40% -> 0 | P15: =O15/30 -> 0 | Q15: =IF(P15<472.56,472.56,P15) -> 472.56
A16: =A15+1 -> 10 | B16: Empleado 10 | C16: Emp 010 | E16: 30 | G16: =E16*F16 -> 0 | H16: =(G16-VLOOKUP(G16,TABLAS!$A$7:$D$17,1))*VLOOKUP(G16,TABLAS!$A$7:$D$17,4)+VLOOKUP(G16,TABLAS!$A$7:$D$17,3) -> #N/A | I16: =IF(G16<=11492.66,(113.14*30.4)*15.02%,0) -> 516.60629 | J16: 0 | K16: =+IF(H16>I16,H16-I16,0) -> #N/A | L16: =+G16-K16 -> #N/A | M16: =+IF(K16>0,(D16-G16+K16),D16-L16) -> #N/A | N16: =IMSS!AK17 -> #N/A | O16: =D16*40% -> 0 | P16: =O16/30 -> 0 | Q16: =IF(P16<472.56,472.56,P16) -> 472.56
A17: =A16+1 -> 11 | B17: Empleado 11 | C17: Emp 011 | E17: 30 | G17: =E17*F17 -> 0 | H17: =(G17-VLOOKUP(G17,TABLAS!$A$7:$D$17,1))*VLOOKUP(G17,TABLAS!$A$7:$D$17,4)+VLOOKUP(G17,TABLAS!$A$7:$D$17,3) -> #N/A | I17: =IF(G17<=11492.66,(113.14*30.4)*15.02%,0) -> 516.60629 | J17: 0 | K17: =+IF(H17>I17,H17-I17,0) -> #N/A | L17: =+G17-K17 -> #N/A | M17: =+IF(K17>0,(D17-G17+K17),D17-L17) -> #N/A | N17: =IMSS!AK18 -> #N/A | O17: =D17*40% -> 0 | P17: =O17/30 -> 0 | Q17: =IF(P17<472.56,472.56,P17) -> 472.56
A18: =A17+1 -> 12 | B18: Empleado 12 | C18: Emp 012 | E18: 30 | G18: =E18*F18 -> 0 | H18: =(G18-VLOOKUP(G18,TABLAS!$A$7:$D$17,1))*VLOOKUP(G18,TABLAS!$A$7:$D$17,4)+VLOOKUP(G18,TABLAS!$A$7:$D$17,3) -> #N/A | I18: =IF(G18<=11492.66,(113.14*30.4)*15.02%,0) -> 516.60629 | J18: 0 | K18: =+IF(H18>I18,H18-I18,0) -> #N/A | L18: =+G18-K18 -> #N/A | M18: =+IF(K18>0,(D18-G18+K18),D18-L18) -> #N/A | N18: =IMSS!AK19 -> #N/A | O18: =D18*40% -> 0 | P18: =O18/30 -> 0 | Q18: =IF(P18<472.56,472.56,P18) -> 472.56
A19: =A18+1 -> 13 | B19: Empleado 13 | C19: Emp 013 | E19: 30 | G19: =E19*F19 -> 0 | H19: =(G19-VLOOKUP(G19,TABLAS!$A$7:$D$17,1))*VLOOKUP(G19,TABLAS!$A$7:$D$17,4)+VLOOKUP(G19,TABLAS!$A$7:$D$17,3) -> #N/A | I19: =IF(G19<=11492.66,(113.14*30.4)*15.02%,0) -> 516.60629 | J19: 0 | K19: =+IF(H19>I19,H19-I19,0) -> #N/A | L19: =+G19-K19 -> #N/A | M19: =+IF(K19>0,(D19-G19+K19),D19-L19) -> #N/A | N19: =IMSS!AK20 -> #N/A | O19: =D19*40% -> 0 | P19: =O19/30 -> 0 | Q19: =IF(P19<472.56,472.56,P19) -> 472.56
... A22: =A21+1 -> 16 | B22: Empleado 16 | C22: Emp 016 | E22: 30 | G22: =E22*F22 -> 0 | H22: =(G22-VLOOKUP(G22,TABLAS!$A$7:$D$17,1))*VLOOKUP(G22,TABLAS!$A$7:$D$17,4)+VLOOKUP(G22,TABLAS!$A$7:$D$17,3) -> #N/A | I22: =IF(G22<=11492.66,(113.14*30.4)*15.02%,0) -> 516.60629 | J22: 0 | K22: =+IF(H22>I22,H22-I22,0) -> #N/A | L22: =+G22-K22 -> #N/A | M22: =+IF(K22>0,(D22-G22+K22),D22-L22) -> #N/A | N22: =IMSS!AK23 -> #N/A | O22: =D22*40% -> 0 | P22: =O22/30 -> 0 | Q22: =IF(P22<472.56,472.56,P22) -> 472.56
A23: =A22+1 -> 17 | B23: Empleado 17 | C23: Emp 017 | E23: 30 | G23: =E23*F23 -> 0 | H23: =(G23-VLOOKUP(G23,TABLAS!$A$7:$D$17,1))*VLOOKUP(G23,TABLAS!$A$7:$D$17,4)+VLOOKUP(G23,TABLAS!$A$7:$D$17,3) -> #N/A | I23: =IF(G23<=11492.66,(113.14*30.4)*15.02%,0) -> 516.60629 | J23: 0 | K23: =+IF(H23>I23,H23-I23,0) -> #N/A | L23: =+G23-K23 -> #N/A | M23: =+IF(K23>0,(D23-G23+K23),D23-L23) -> #N/A | N23: =IMSS!#REF! -> #REF! | O23: =D23*40% -> 0 | P23: =O23/30 -> 0 | Q23: =IF(P23<472.56,472.56,P23) -> 472.56
A24: =A23+1 -> 18 | B24: Empleado 18 | C24: Emp 018 | E24: 30 | G24: =E24*F24 -> 0 | H24: =(G24-VLOOKUP(G24,TABLAS!$A$7:$D$17,1))*VLOOKUP(G24,TABLAS!$A$7:$D$17,4)+VLOOKUP(G24,TABLAS!$A$7:$D$17,3) -> #N/A | I24: =IF(G24<=11492.66,(113.14*30.4)*15.02%,0) -> 516.60629 | J24: 0 | K24: =+IF(H24>I24,H24-I24,0) -> #N/A | L24: =+G24-K24 -> #N/A | M24: =+IF(K24>0,(D24-G24+K24),D24-L24) -> #N/A | N24: =IMSS!AK106 -> 0 | O24: =D24*40% -> 0 | P24: =O24/30 -> 0 | Q24: =IF(P24<472.56,472.56,P24) -> 472.56
A25: =A24+1 -> 19 | B25: Empleado 19 | C25: Emp 019 | E25: 30 | G25: =E25*F25 -> 0 | H25: =(G25-VLOOKUP(G25,TABLAS!$A$7:$D$17,1))*VLOOKUP(G25,TABLAS!$A$7:$D$17,4)+VLOOKUP(G25,TABLAS!$A$7:$D$17,3) -> #N/A | I25: =IF(G25<=11492.66,(113.14*30.4)*15.02%,0) -> 516.60629 | J25: 0 | K25: =+IF(H25>I25,H25-I25,0) -> #N/A | L25: =+G25-K25 -> #N/A | M25: =+IF(K25>0,(D25-G25+K25),D25-L25) -> #N/A | N25: =IMSS!AK107 -> #N/A | O25: =D25*40% -> 0 | P25: =O25/30 -> 0 | Q25: =IF(P25<472.56,472.56,P25) -> 472.56
A26: =A25+1 -> 20 | B26: Empleado 20 | C26: Emp 020 | E26: 30 | G26: =E26*F26 -> 0 | H26: =(G26-VLOOKUP(G26,TABLAS!$A$7:$D$17,1))*VLOOKUP(G26,TABLAS!$A$7:$D$17,4)+VLOOKUP(G26,TABLAS!$A$7:$D$17,3) -> #N/A | I26: =IF(G26<=11492.66,(113.14*30.4)*15.02%,0) -> 516.60629 | J26: 0 | K26: =+IF(H26>I26,H26-I26,0) -> #N/A | L26: =+G26-K26 -> #N/A | M26: =+IF(K26>0,(D26-G26+K26),D26-L26) -> #N/A | N26: =IMSS!AK108 -> 0 | O26: =D26*40% -> 0 | P26: =O26/30 -> 0 | Q26: =IF(P26<472.56,472.56,P26) -> 472.56
A27: =A26+1 -> 21 | B27: Empleado 21 | C27: Emp 021 | E27: 30 | G27: =E27*F27 -> 0 | H27: =(G27-VLOOKUP(G27,TABLAS!$A$7:$D$17,1))*VLOOKUP(G27,TABLAS!$A$7:$D$17,4)+VLOOKUP(G27,TABLAS!$A$7:$D$17,3) -> #N/A | I27: =IF(G27<=11492.66,(113.14*30.4)*15.02%,0) -> 516.60629 | J27: 0 | K27: =+IF(H27>I27,H27-I27,0) -> #N/A | L27: =+G27-K27 -> #N/A | M27: =+IF(K27>0,(D27-G27+K27),D27-L27) -> #N/A | N27: =IMSS!AK109 -> 0 | O27: =D27*40% -> 0 | P27: =O27/30 -> 0 | Q27: =IF(P27<472.56,472.56,P27) -> 472.56
A28: =A27+1 -> 22 | B28: Empleado 22 | C28: Emp 022 | E28: 30 | G28: =E28*F28 -> 0 | H28: =(G28-VLOOKUP(G28,TABLAS!$A$7:$D$17,1))*VLOOKUP(G28,TABLAS!$A$7:$D$17,4)+VLOOKUP(G28,TABLAS!$A$7:$D$17,3) -> #N/A | I28: =IF(G28<=11492.66,(113.14*30.4)*15.02%,0) -> 516.60629 | J28: 0 | K28: =+IF(H28>I28,H28-I28,0) -> #N/A | L28: =+G28-K28 -> #N/A | M28: =+IF(K28>0,(D28-G28+K28),D28-L28) -> #N/A | N28: =IMSS!AK110 -> 0 | O28: =D28*40% -> 0 | P28: =O28/30 -> 0 | Q28: =IF(P28<472.56,472.56,P28) -> 472.56
A29: =A28+1 -> 23 | B29: Empleado 23 | C29: Emp 023 | E29: 30 | G29: =E29*F29 -> 0 | H29: =(G29-VLOOKUP(G29,TABLAS!$A$7:$D$17,1))*VLOOKUP(G29,TABLAS!$A$7:$D$17,4)+VLOOKUP(G29,TABLAS!$A$7:$D$17,3) -> #N/A | I29: =IF(G29<=11492.66,(113.14*30.4)*15.02%,0) -> 516.60629 | J29: 0 | K29: =+IF(H29>I29,H29-I29,0) -> #N/A | L29: =+G29-K29 -> #N/A | M29: =+IF(K29>0,(D29-G29+K29),D29-L29) -> #N/A | N29: =IMSS!AK111 -> 0 | O29: =D29*40% -> 0 | P29: =O29/30 -> 0 | Q29: =IF(P29<472.56,472.56,P29) -> 472.56
A30: =A29+1 -> 24 | B30: Empleado 24 | C30: Emp 024 | E30: 30 | G30: =E30*F30 -> 0 | H30: =(G30-VLOOKUP(G30,TABLAS!$A$7:$D$17,1))*VLOOKUP(G30,TABLAS!$A$7:$D$17,4)+VLOOKUP(G30,TABLAS!$A$7:$D$17,3) -> #N/A | I30: =IF(G30<=11492.66,(113.14*30.4)*15.02%,0) -> 516.60629 | J30: 0 | K30: =+IF(H30>I30,H30-I30,0) -> #N/A | L30: =+G30-K30 -> #N/A | M30: =+IF(K30>0,(D30-G30+K30),D30-L30) -> #N/A | N30: =IMSS!AK112 -> 0 | O30: =D30*40% -> 0 | P30: =O30/30 -> 0 | Q30: =IF(P30<472.56,472.56,P30) -> 472.56
A31: =A30+1 -> 25 | B31: Empleado 25 | C31: Emp 025 | E31: 30 | G31: =E31*F31 -> 0 | H31: =(G31-VLOOKUP(G31,TABLAS!$A$7:$D$17,1))*VLOOKUP(G31,TABLAS!$A$7:$D$17,4)+VLOOKUP(G31,TABLAS!$A$7:$D$17,3) -> #N/A | I31: =IF(G31<=11492.66,(113.14*30.4)*15.02%,0) -> 516.60629 | J31: 0 | K31: =+IF(H31>I31,H31-I31,0) -> #N/A | L31: =+G31-K31 -> #N/A | M31: =+IF(K31>0,(D31-G31+K31),D31-L31) -> #N/A | N31: =IMSS!AK113 -> 0 | O31: =D31*40% -> 0 | P31: =O31/30 -> 0 | Q31: =IF(P31<472.56,472.56,P31) -> 472.56
A32: =A31+1 -> 26 | B32: Empleado 26 | C32: Emp 026 | E32: 30 | G32: =E32*F32 -> 0 | H32: =(G32-VLOOKUP(G32,TABLAS!$A$7:$D$17,1))*VLOOKUP(G32,TABLAS!$A$7:$D$17,4)+VLOOKUP(G32,TABLAS!$A$7:$D$17,3) -> #N/A | I32: =IF(G32<=11492.66,(113.14*30.4)*15.02%,0) -> 516.60629 | J32: 0 | K32: =+IF(H32>I32,H32-I32,0) -> #N/A | L32: =+G32-K32 -> #N/A | M32: =+IF(K32>0,(D32-G32+K32),D32-L32) -> #N/A | N32: =IMSS!AK114 -> 0 | O32: =D32*40% -> 0 | P32: =O32/30 -> 0 | Q32: =IF(P32<472.56,472.56,P32) -> 472.56
A33: =A32+1 -> 27 | B33: Empleado 27 | C33: Emp 027 | E33: 30 | G33: =E33*F33 -> 0 | H33: =(G33-VLOOKUP(G33,TABLAS!$A$7:$D$17,1))*VLOOKUP(G33,TABLAS!$A$7:$D$17,4)+VLOOKUP(G33,TABLAS!$A$7:$D$17,3) -> #N/A | I33: =IF(G33<=11492.66,(113.14*30.4)*15.02%,0) -> 516.60629 | J33: 0 | K33: =+IF(H33>I33,H33-I33,0) -> #N/A | L33: =+G33-K33 -> #N/A | M33: =+IF(K33>0,(D33-G33+K33),D33-L33) -> #N/A | N33: =IMSS!AK115 -> 0 | O33: =D33*40% -> 0 | P33: =O33/30 -> 0 | Q33: =IF(P33<472.56,472.56,P33) -> 472.56
A34: =A33+1 -> 28 | B34: Empleado 28 | C34: Emp 028 | E34: 30 | G34: =E34*F34 -> 0 | H34: =(G34-VLOOKUP(G34,TABLAS!$A$7:$D$17,1))*VLOOKUP(G34,TABLAS!$A$7:$D$17,4)+VLOOKUP(G34,TABLAS!$A$7:$D$17,3) -> #N/A | I34: =IF(G34<=11492.66,(113.14*30.4)*15.02%,0) -> 516.60629 | J34: 0 | K34: =+IF(H34>I34,H34-I34,0) -> #N/A | L34: =+G34-K34 -> #N/A | M34: =+IF(K34>0,(D34-G34+K34),D34-L34) -> #N/A | N34: =IMSS!AK116 -> 0 | O34: =D34*40% -> 0 | P34: =O34/30 -> 0 | Q34: =IF(P34<472.56,472.56,P34) -> 472.56
A35: =A34+1 -> 29 | B35: Empleado 29 | C35: Emp 029 | E35: 30 | G35: =E35*F35 -> 0 | H35: =(G35-VLOOKUP(G35,TABLAS!$A$7:$D$17,1))*VLOOKUP(G35,TABLAS!$A$7:$D$17,4)+VLOOKUP(G35,TABLAS!$A$7:$D$17,3) -> #N/A | I35: =IF(G35<=11492.66,(113.14*30.4)*15.02%,0) -> 516.60629 | J35: 0 | K35: =+IF(H35>I35,H35-I35,0) -> #N/A | L35: =+G35-K35 -> #N/A | M35: =+IF(K35>0,(D35-G35+K35),D35-L35) -> #N/A | N35: =IMSS!AK117 -> 0 | O35: =D35*40% -> 0 | P35: =O35/30 -> 0 | Q35: =IF(P35<472.56,472.56,P35) -> 472.56
... A104: =A103+1 -> 98 | B104: Empleado 98 | C104: Emp 098 | E104: 30 | G104: =E104*F104 -> 0 | H104: =(G104-VLOOKUP(G104,TABLAS!$A$7:$D$17,1))*VLOOKUP(G104,TABLAS!$A$7:$D$17,4)+VLOOKUP(G104,TABLAS!$A$7:$D$17,3) -> #N/A | I104: =IF(G104<=11492.66,(113.14*30.4)*15.02%,0) -> 516.60629 | J104: 0 | K104: =+IF(H104>I104,H104-I104,0) -> #N/A | L104: =+G104-K104 -> #N/A | M104: =+IF(K104>0,(D104-G104+K104),D104-L104) -> #N/A | N104: =IMSS!AK186 -> 0 | O104: =D104*40% -> 0 | P104: =O104/30 -> 0 | Q104: =IF(P104<472.56,472.56,P104) -> 472.56
B106: SUMA | D106: =SUM(D7:D104) -> 0 | G106: =SUM(G7:G104) -> 0 | H106: =SUM(H7:H104) -> #N/A | I106: =SUM(I7:I104) -> 50627.417 | J106: =SUM(J7:J104) -> 0 | K106: =SUM(K7:K104) -> #N/A | L106: =SUM(L7:L104) -> #N/A | M106: =SUM(M7:M104) -> #N/A | N106: =SUM(N7:N104) -> #N/A
B108: DESGLOCE DE FACTURA
C109: SUELDO | D109: PPS/IRT | E109: TOTAL
B110: COSTO NOMINA | C110: =G106+J106 -> 0 | D110: =+M106 -> #N/A | E110: =C110+D110 -> #N/A
B111: COSTO CARGA FISCAL | E111: =+N106 -> #N/A | K111: COSTO IMSS E INF REAL | L111: ='IMSS REAL'!AL106 -> #N/A
B112: NOMINA + CARGAS | E112: =SUM(E110:E111) -> #N/A | K112: AHORRO MENSUAL | L112: =L111-N106 -> #N/A
B113: COMISIÓN | D113: 0.06 | E113: =E112*D113 -> #N/A | K113: AHORRO ANUAL | L113: =L112*12 -> #N/A
B114: SUBTOTAL | E114: =E112+E113 -> #N/A
B115: IVA | D115: 0.16 | E115: =E114*D115 -> #N/A
...

Sheet IMSS
L1: SMGDF | M1: 3 SMGDF
A2: IMSS | L2: 117.31 | M2: =+L2*3 -> 351.93 | R2: =+H8*M8 -> 0 | S2: 1
R3: =+R8 -> 0 | S3: 0.053344
N4: ENFERMEDADES Y MATERNIDAD | V4: < | AB4: COSTO SOCIAL | AG4: INGRESO | AJ4: UITILIDAD
A5: N° | F5: NOMBRE | G5: CLAVE | H5: DIAS | I5: DIAS COTIZADOS | J5: DIAS INCAPACIDAD | K5: DIAS AUSENTISMO | L5: SALARIO DIARIO | M5: SBC | N5: CUOTA FIJA | O5: EXCEDENTE | P5: PREST EN DINERO | Q5: PREST EN ESPECIE | R5: RIESGO DE TRAB | S5: INVALIDEZ Y VIDA | T5: GUARDERIAS | U5: TOTAL IMSS MENSUAL | W5: RETIRO | X5: CESANTIA Y VEJEZ | Y5: INFONAVIT | Z5: TOTAL BIMESTRAL | AB5: TOTAL MENSUAL | AC5: TOTAL RCV E INF | AD5: 4% NOMINA | AE5: TOTAL COSTO | AG5: INGRESO | AH5: IVA | AI5: TOTAL INGRESO | AK5: COSTO POR PERIODO | AL5: COSTO POR DIA
N6: 0.204 | O6: 0.015 | P6: 0.0095 | Q6: 0.01425 | R6: 0.005 | S6: 0.02375 | T6: 0.01 | W6: 0.02 | Y6: 0.05
A8: =A7+1 -> 1 | F8: =NOMINA!B7 -> Empleado 1 | G8: =NOMINA!C7 -> Emp 001 | H8: =+I8-J8-K8 -> 31 | I8: 31 | J8: 0 | K8: 0 | L8: =+NOMINA!F7 -> 0 | M8: =IF(L8*1.0493>$L$2*25,$L$2*25,L8*1.0493) -> 0 | N8: =+ROUND($L$2*$N$6*I8,2) -> 741.87 | O8: =+IF(M8>$M$2,M8-$M$2,0)*$O$6*I8 -> 0 | P8: =+ROUND(M8*$P$6*I8,2) -> 0 | Q8: =+ROUND(M8*$Q$6*I8,2) -> 0 | R8: =+ROUND(M8*$R$6*I8,2) -> 0 | S8: =+ROUND(M8*$S$6*I8,2) -> 0 | T8: =+ROUND(M8*$T$6*I8,2) -> 0 | U8: =+SUM(N8:T8) -> 741.87 | W8: =+ROUND(I8*M8*$W$6,2) -> 0 | X8: =+ROUND(H8*M8*(VLOOKUP(M8,TABLAS!$B$29:$D$35,3,1)+1.125%),2) -> #N/A | Y8: =+ROUND(H8*M8*$Y$6,2) -> 0 | Z8: =+SUM(W8:Y8) -> #N/A | AB8: =+U8 -> 741.87 | AC8: =+Z8 -> #N/A | AD8: =+H8*L8*4% -> 0 | AE8: =+SUM(AB8:AD8) -> #N/A | AG8: =+AE8+AJ8 -> #N/A | AH8: =+AG8*16% -> #N/A | AI8: =+AG8+AH8 -> #N/A | AJ8: =+AE8*7.21% -> #N/A | AK8: =AL8*31 -> #N/A | AL8: =AE8/30.4 -> #N/A
A9: =A8+1 -> 2 | F9: =NOMINA!B8 -> Empleado 2 | G9: =NOMINA!C8 -> Emp 002 | H9: =+I9-J9-K9 -> 31 | I9: 31 | J9: 0 | K9: 0 | L9: =+NOMINA!F8 -> 0 | M9: =IF(L9*1.0493>$L$2*25,$L$2*25,L9*1.0493) -> 0 | N9: =+ROUND($L$2*$N$6*I9,2) -> 741.87 | O9: =+IF(M9>$M$2,M9-$M$2,0)*$O$6*I9 -> 0 | P9: =+ROUND(M9*$P$6*I9,2) -> 0 | Q9: =+ROUND(M9*$Q$6*I9,2) -> 0 | R9: =+ROUND(M9*$R$6*I9,2) -> 0 | S9: =+ROUND(M9*$S$6*I9,2) -> 0 | T9: =+ROUND(M9*$T$6*I9,2) -> 0 | U9: =+SUM(N9:T9) -> 741.87 | W9: =+ROUND(I9*M9*$W$6,2) -> 0 | X9: =+ROUND(H9*M9*(VLOOKUP(M9,TABLAS!$B$29:$D$35,3,1)+1.125%),2) -> #N/A | Y9: =+ROUND(H9*M9*$Y$6,2) -> 0 | Z9: =+SUM(W9:Y9) -> #N/A | AB9: =+U9 -> 741.87 | AC9: =+Z9 -> #N/A | AD9: =+H9*L9*4% -> 0 | AE9: =+SUM(AB9:AD9) -> #N/A | AG9: =+AE9+AJ9 -> #N/A | AH9: =+AG9*16% -> #N/A | AI9: =+AG9+AH9 -> #N/A | AJ9: =+AE9*7.21% -> #N/A | AK9: =AL9*31 -> #N/A | AL9: =AE9/30.4 -> #N/A
A10: =A9+1 -> 3 | F10: =NOMINA!B9 -> Empleado 3 | G10: =NOMINA!C9 -> Emp 003 | H10: =+I10-J10-K10 -> 31 | I10: 31 | J10: 0 | K10: 0 | L10: =+NOMINA!F9 -> 0 | M10: =IF(L10*1.0493>$L$2*25,$L$2*25,L10*1.0493) -> 0 | N10: =+ROUND($L$2*$N$6*I10,2) -> 741.87 | O10: =+IF(M10>$M$2,M10-$M$2,0)*$O$6*I10 -> 0 | P10: =+ROUND(M10*$P$6*I10,2) -> 0 | Q10: =+ROUND(M10*$Q$6*I10,2) -> 0 | R10: =+ROUND(M10*$R$6*I10,2) -> 0 | S10: =+ROUND(M10*$S$6*I10,2) -> 0 | T10: =+ROUND(M10*$T$6*I10,2) -> 0 | U10: =+SUM(N10:T10) -> 741.87 | W10: =+ROUND(I10*M10*$W$6,2) -> 0 | X10: =+ROUND(H10*M10*(VLOOKUP(M10,TABLAS!$B$29:$D$35,3,1)+1.125%),2) -> #N/A | Y10: =+ROUND(H10*M10*$Y$6,2) -> 0 | Z10: =+SUM(W10:Y10) -> #N/A | AB10: =+U10 -> 741.87 | AC10: =+Z10 -> #N/A | AD10: =+H10*L10*4% -> 0 | AE10: =+SUM(AB10:AD10) -> #N/A | AG10: =+AE10+AJ10 -> #N/A | AH10: =+AG10*16% -> #N/A | AI10: =+AG10+AH10 -> #N/A | AJ10: =+AE10*7.21% -> #N/A | AK10: =AL10*31 -> #N/A | AL10: =AE10/30.4 -> #N/A
A11: =A10+1 -> 4 | F11: =NOMINA!B10 -> Empleado 4 | G11: =NOMINA!C10 -> Emp 004 | H11: =+I11-J11-K11 -> 31 | I11: 31 | J11: 0 | K11: 0 | L11: =+NOMINA!F10 -> 0 | M11: =IF(L11*1.0493>$L$2*25,$L$2*25,L11*1.0493) -> 0 | N11: =+ROUND($L$2*$N$6*I11,2) -> 741.87 | O11: =+IF(M11>$M$2,M11-$M$2,0)*$O$6*I11 -> 0 | P11: =+ROUND(M11*$P$6*I11,2) -> 0 | Q11: =+ROUND(M11*$Q$6*I11,2) -> 0 | R11: =+ROUND(M11*$R$6*I11,2) -> 0 | S11: =+ROUND(M11*$S$6*I11,2) -> 0 | T11: =+ROUND(M11*$T$6*I11,2) -> 0 | U11: =+SUM(N11:T11) -> 741.87 | W11: =+ROUND(I11*M11*$W$6,2) -> 0 | X11: =+ROUND(H11*M11*(VLOOKUP(M11,TABLAS!$B$29:$D$35,3,1)+1.125%),2) -> #N/A | Y11: =+ROUND(H11*M11*$Y$6,2) -> 0 | Z11: =+SUM(W11:Y11) -> #N/A | AB11: =+U11 -> 741.87 | AC11: =+Z11 -> #N/A | AD11: =+H11*L11*4% -> 0 | AE11: =+SUM(AB11:AD11) -> #N/A | AG11: =+AE11+AJ11 -> #N/A | AH11: =+AG11*16% -> #N/A | AI11: =+AG11+AH11 -> #N/A | AJ11: =+AE11*7.21% -> #N/A | AK11: =AL11*31 -> #N/A | AL11: =AE11/30.4 -> #N/A
A12: =A11+1 -> 5 | F12: =NOMINA!B11 -> Empleado 5 | G12: =NOMINA!C11 -> Emp 005 | H12: =+I12-J12-K12 -> 31 | I12: 31 | J12: 0 | K12: 0 | L12: =+NOMINA!F11 -> 0 | M12: =IF(L12*1.0493>$L$2*25,$L$2*25,L12*1.0493) -> 0 | N12: =+ROUND($L$2*$N$6*I12,2) -> 741.87 | O12: =+IF(M12>$M$2,M12-$M$2,0)*$O$6*I12 -> 0 | P12: =+ROUND(M12*$P$6*I12,2) -> 0 | Q12: =+ROUND(M12*$Q$6*I12,2) -> 0 | R12: =+ROUND(M12*$R$6*I12,2) -> 0 | S12: =+ROUND(M12*$S$6*I12,2) -> 0 | T12: =+ROUND(M12*$T$6*I12,2) -> 0 | U12: =+SUM(N12:T12) -> 741.87 | W12: =+ROUND(I12*M12*$W$6,2) -> 0 | X12: =+ROUND(H12*M12*(VLOOKUP(M12,TABLAS!$B$29:$D$35,3,1)+1.125%),2) -> #N/A | Y12: =+ROUND(H12*M12*$Y$6,2) -> 0 | Z12: =+SUM(W12:Y12) -> #N/A | AB12: =+U12 -> 741.87 | AC12: =+Z12 -> #N/A | AD12: =+H12*L12*4% -> 0 | AE12: =+SUM(AB12:AD12) -> #N/A | AG12: =+AE12+AJ12 -> #N/A | AH12: =+AG12*16% -> #N/A | AI12: =+AG12+AH12 -> #N/A | AJ12: =+AE12*7.21% -> #N/A | AK12: =AL12*31 -> #N/A | AL12: =AE12/30.4 -> #N/A
A13: =A12+1 -> 6 | F13: =NOMINA!B12 -> Empleado 6 | G13: =NOMINA!C12 -> Emp 006 | H13: =+I13-J13-K13 -> 31 | I13: 31 | J13: 0 | K13: 0 | L13: =+NOMINA!F12 -> 0 | M13: =IF(L13*1.0493>$L$2*25,$L$2*25,L13*1.0493) -> 0 | N13: =+ROUND($L$2*$N$6*I13,2) -> 741.87 | O13: =+IF(M13>$M$2,M13-$M$2,0)*$O$6*I13 -> 0 | P13: =+ROUND(M13*$P$6*I13,2) -> 0 | Q13: =+ROUND(M13*$Q$6*I13,2) -> 0 | R13: =+ROUND(M13*$R$6*I13,2) -> 0 | S13: =+ROUND(M13*$S$6*I13,2) -> 0 | T13: =+ROUND(M13*$T$6*I13,2) -> 0 | U13: =+SUM(N13:T13) -> 741.87 | W13: =+ROUND(I13*M13*$W$6,2) -> 0 | X13: =+ROUND(H13*M13*(VLOOKUP(M13,TABLAS!$B$29:$D$35,3,1)+1.125%),2) -> #N/A | Y13: =+ROUND(H13*M13*$Y$6,2) -> 0 | Z13: =+SUM(W13:Y13) -> #N/A | AB13: =+U13 -> 741.87 | AC13: =+Z13 -> #N/A | AD13: =+H13*L13*4% -> 0 | AE13: =+SUM(AB13:AD13) -> #N/A | AG13: =+AE13+AJ13 -> #N/A | AH13: =+AG13*16% -> #N/A | AI13: =+AG13+AH13 -> #N/A | AJ13: =+AE13*7.21% -> #N/A | AK13: =AL13*31 -> #N/A | AL13: =AE13/30.4 -> #N/A
A14: =A13+1 -> 7 | F14: =NOMINA!B13 -> Empleado 7 | G14: =NOMINA!C13 -> Emp 007 | H14: =+I14-J14-K14 -> 31 | I14: 31 | J14: 0 | K14: 0 | L14: =+NOMINA!F13 -> 0 | M14: =IF(L14*1.0493>$L$2*25,$L$2*25,L14*1.0493) -> 0 | N14: =+ROUND($L$2*$N$6*I14,2) -> 741.87 | O14: =+IF(M14>$M$2,M14-$M$2,0)*$O$6*I14 -> 0 | P14: =+ROUND(M14*$P$6*I14,2) -> 0 | Q14: =+ROUND(M14*$Q$6*I14,2) -> 0 | R14: =+ROUND(M14*$R$6*I14,2) -> 0 | S14: =+ROUND(M14*$S$6*I14,2) -> 0 | T14: =+ROUND(M14*$T$6*I14,2) -> 0 | U14: =+SUM(N14:T14) -> 741.87 | W14: =+ROUND(I14*M14*$W$6,2) -> 0 | X14: =+ROUND(H14*M14*(VLOOKUP(M14,TABLAS!$B$29:$D$35,3,1)+1.125%),2) -> #N/A | Y14: =+ROUND(H14*M14*$Y$6,2) -> 0 | Z14: =+SUM(W14:Y14) -> #N/A | AB14: =+U14 -> 741.87 | AC14: =+Z14 -> #N/A | AD14: =+H14*L14*4% -> 0 | AE14: =+SUM(AB14:AD14) -> #N/A | AG14: =+AE14+AJ14 -> #N/A | AH14: =+AG14*16% -> #N/A | AI14: =+AG14+AH14 -> #N/A | AJ14: =+AE14*7.21% -> #N/A | AK14: =AL14*31 -> #N/A | AL14: =AE14/30.4 -> #N/A
A15: =A14+1 -> 8 | F15: =NOMINA!B14 -> Empleado 8 | G15: =NOMINA!C14 -> Emp 008 | H15: =+I15-J15-K15 -> 31 | I15: 31 | J15: 0 | K15: 0 | L15: =+NOMINA!F14 -> 0 | M15: =IF(L15*1.0493>$L$2*25,$L$2*25,L15*1.0493) -> 0 | N15: =+ROUND($L$2*$N$6*I15,2) -> 741.87 | O15: =+IF(M15>$M$2,M15-$M$2,0)*$O$6*I15 -> 0 | P15: =+ROUND(M15*$P$6*I15,2) -> 0 | Q15: =+ROUND(M15*$Q$6*I15,2) -> 0 | R15: =+ROUND(M15*$R$6*I15,2) -> 0 | S15: =+ROUND(M15*$S$6*I15,2) -> 0 | T15: =+ROUND(M15*$T$6*I15,2) -> 0 | U15: =+SUM(N15:T15) -> 741.87 | W15: =+ROUND(I15*M15*$W$6,2) -> 0 | X15: =+ROUND(H15*M15*(VLOOKUP(M15,TABLAS!$B$29:$D$35,3,1)+1.125%),2) -> #N/A | Y15: =+ROUND(H15*M15*$Y$6,2) -> 0 | Z15: =+SUM(W15:Y15) -> #N/A | AB15: =+U15 -> 741.87 | AC15: =+Z15 -> #N/A | AD15: =+H15*L15*4% -> 0 | AE15: =+SUM(AB15:AD15) -> #N/A | AG15: =+AE15+AJ15 -> #N/A | AH15: =+AG15*16% -> #N/A | AI15: =+AG15+AH15 -> #N/A | AJ15: =+AE15*7.21% -> #N/A | AK15: =AL15*31 -> #N/A | AL15: =AE15/30.4 -> #N/A
A16: =A15+1 -> 9 | F16: =NOMINA!B15 -> Empleado 9 | G16: =NOMINA!C15 -> Emp 009 | H16: =+I16-J16-K16 -> 31 | I16: 31 | J16: 0 | K16: 0 | L16: =+NOMINA!F15 -> 0 | M16: =IF(L16*1.0493>$L$2*25,$L$2*25,L16*1.0493) -> 0 | N16: =+ROUND($L$2*$N$6*I16,2) -> 741.87 | O16: =+IF(M16>$M$2,M16-$M$2,0)*$O$6*I16 -> 0 | P16: =+ROUND(M16*$P$6*I16,2) -> 0 | Q16: =+ROUND(M16*$Q$6*I16,2) -> 0 | R16: =+ROUND(M16*$R$6*I16,2) -> 0 | S16: =+ROUND(M16*$S$6*I16,2) -> 0 | T16: =+ROUND(M16*$T$6*I16,2) -> 0 | U16: =+SUM(N16:T16) -> 741.87 | W16: =+ROUND(I16*M16*$W$6,2) -> 0 | X16: =+ROUND(H16*M16*(VLOOKUP(M16,TABLAS!$B$29:$D$35,3,1)+1.125%),2) -> #N/A | Y16: =+ROUND(H16*M16*$Y$6,2) -> 0 | Z16: =+SUM(W16:Y16) -> #N/A | AB16: =+U16 -> 741.87 | AC16: =+Z16 -> #N/A | AD16: =+H16*L16*4% -> 0 | AE16: =+SUM(AB16:AD16) -> #N/A | AG16: =+AE16+AJ16 -> #N/A | AH16: =+AG16*16% -> #N/A | AI16: =+AG16+AH16 -> #N/A | AJ16: =+AE16*7.21% -> #N/A | AK16: =AL16*31 -> #N/A | AL16: =AE16/30.4 -> #N/A
A17: =A16+1 -> 10 | F17: =NOMINA!B16 -> Empleado 10 | G17: =NOMINA!C16 -> Emp 010 | H17: =+I17-J17-K17 -> 31 | I17: 31 | J17: 0 | K17: 0 | L17: =+NOMINA!F16 -> 0 | M17: =IF(L17*1.0493>$L$2*25,$L$2*25,L17*1.0493) -> 0 | N17: =+ROUND($L$2*$N$6*I17,2) -> 741.87 | O17: =+IF(M17>$M$2,M17-$M$2,0)*$O$6*I17 -> 0 | P17: =+ROUND(M17*$P$6*I17,2) -> 0 | Q17: =+ROUND(M17*$Q$6*I17,2) -> 0 | R17: =+ROUND(M17*$R$6*I17,2) -> 0 | S17: =+ROUND(M17*$S$6*I17,2) -> 0 | T17: =+ROUND(M17*$T$6*I17,2) -> 0 | U17: =+SUM(N17:T17) -> 741.87 | W17: =+ROUND(I17*M17*$W$6,2) -> 0 | X17: =+ROUND(H17*M17*(VLOOKUP(M17,TABLAS!$B$29:$D$35,3,1)+1.125%),2) -> #N/A | Y17: =+ROUND(H17*M17*$Y$6,2) -> 0 | Z17: =+SUM(W17:Y17) -> #N/A | AB17: =+U17 -> 741.87 | AC17: =+Z17 -> #N/A | AD17: =+H17*L17*4% -> 0 | AE17: =+SUM(AB17:AD17) -> #N/A | AG17: =+AE17+AJ17 -> #N/A | AH17: =+AG17*16% -> #N/A | AI17: =+AG17+AH17 -> #N/A | AJ17: =+AE17*7.21% -> #N/A | AK17: =AL17*31 -> #N/A | AL17: =AE17/30.4 -> #N/A
A18: =A17+1 -> 11 | F18: =NOMINA!B17 -> Empleado 11 | G18: =NOMINA!C17 -> Emp 011 | H18: =+I18-J18-K18 -> 31 | I18: 31 | J18: 0 | K18: 0 | L18: =+NOMINA!F17 -> 0 | M18: =IF(L18*1.0493>$L$2*25,$L$2*25,L18*1.0493) -> 0 | N18: =+ROUND($L$2*$N$6*I18,2) -> 741.87 | O18: =+IF(M18>$M$2,M18-$M$2,0)*$O$6*I18 -> 0 | P18: =+ROUND(M18*$P$6*I18,2) -> 0 | Q18: =+ROUND(M18*$Q$6*I18,2) -> 0 | R18: =+ROUND(M18*$R$6*I18,2) -> 0 | S18: =+ROUND(M18*$S$6*I18,2) -> 0 | T18: =+ROUND(M18*$T$6*I18,2) -> 0 | U18: =+SUM(N18:T18) -> 741.87 | W18: =+ROUND(I18*M18*$W$6,2) -> 0 | X18: =+ROUND(H18*M18*(VLOOKUP(M18,TABLAS!$B$29:$D$35,3,1)+1.125%),2) -> #N/A | Y18: =+ROUND(H18*M18*$Y$6,2) -> 0 | Z18: =+SUM(W18:Y18) -> #N/A | AB18: =+U18 -> 741.87 | AC18: =+Z18 -> #N/A | AD18: =+H18*L18*4% -> 0 | AE18: =+SUM(AB18:AD18) -> #N/A | AG18: =+AE18+AJ18 -> #N/A | AH18: =+AG18*16% -> #N/A | AI18: =+AG18+AH18 -> #N/A | AJ18: =+AE18*7.21% -> #N/A | AK18: =AL18*31 -> #N/A | AL18: =AE18/30.4 -> #N/A
A19: =A18+1 -> 12 | F19: =NOMINA!B18 -> Empleado 12 | G19: =NOMINA!C18 -> Emp 012 | H19: =+I19-J19-K19 -> 31 | I19: 31 | J19: 0 | K19: 0 | L19: =+NOMINA!F18 -> 0 | M19: =IF(L19*1.0493>$L$2*25,$L$2*25,L19*1.0493) -> 0 | N19: =+ROUND($L$2*$N$6*I19,2) -> 741.87 | O19: =+IF(M19>$M$2,M19-$M$2,0)*$O$6*I19 -> 0 | P19: =+ROUND(M19*$P$6*I19,2) -> 0 | Q19: =+ROUND(M19*$Q$6*I19,2) -> 0 | R19: =+ROUND(M19*$R$6*I19,2) -> 0 | S19: =+ROUND(M19*$S$6*I19,2) -> 0 | T19: =+ROUND(M19*$T$6*I19,2) -> 0 | U19: =+SUM(N19:T19) -> 741.87 | W19: =+ROUND(I19*M19*$W$6,2) -> 0 | X19: =+ROUND(H19*M19*(VLOOKUP(M19,TABLAS!$B$29:$D$35,3,1)+1.125%),2) -> #N/A | Y19: =+ROUND(H19*M19*$Y$6,2) -> 0 | Z19: =+SUM(W19:Y19) -> #N/A | AB19: =+U19 -> 741.87 | AC19: =+Z19 -> #N/A | AD19: =+H19*L19*4% -> 0 | AE19: =+SUM(AB19:AD19) -> #N/A | AG19: =+AE19+AJ19 -> #N/A | AH19: =+AG19*16% -> #N/A | AI19: =+AG19+AH19 -> #N/A | AJ19: =+AE19*7.21% -> #N/A | AK19: =AL19*31 -> #N/A | AL19: =AE19/30.4 -> #N/A
... A105: =A104+1 -> 98 | F105: =NOMINA!B104 -> Empleado 98 | G105: =NOMINA!C104 -> Emp 098 | H105: =+I105-J105-K105 -> 31 | I105: 31 | J105: 0 | K105: 0 | L105: =+NOMINA!F104 -> 0 | M105: =IF(L105*1.0493>$L$2*25,$L$2*25,L105*1.0493) -> 0 | N105: =+ROUND($L$2*$N$6*I105,2) -> 741.87 | O105: =+IF(M105>$M$2,M105-$M$2,0)*$O$6*I105 -> 0 | P105: =+ROUND(M105*$P$6*I105,2) -> 0 | Q105: =+ROUND(M105*$Q$6*I105,2) -> 0 | R105: =+ROUND(M105*$R$6*I105,2) -> 0 | S105: =+ROUND(M105*$S$6*I105,2) -> 0 | T105: =+ROUND(M105*$T$6*I105,2) -> 0 | U105: =+SUM(N105:T105) -> 741.87 | W105: =+ROUND(I105*M105*$W$6,2) -> 0 | X105: =+ROUND(H105*M105*(VLOOKUP(M105,TABLAS!$B$29:$D$35,3,1)+1.125%),2) -> #N/A | Y105: =+ROUND(H105*M105*$Y$6,2) -> 0 | Z105: =+SUM(W105:Y105) -> #N/A | AB105: =+U105 -> 741.87 | AC105: =+Z105 -> #N/A | AD105: =+H105*L105*4% -> 0 | AE105: =+SUM(AB105:AD105) -> #N/A | AG105: =+AE105+AJ105 -> #N/A | AH105: =+AG105*16% -> #N/A | AI105: =+AG105+AH105 -> #N/A | AJ105: =+AE105*7.21% -> #N/A | AK105: =AL105*31 -> #N/A | AL105: =AE105/30.4 -> #N/A
F107: SUMA | N107: =SUM(N8:N105) -> 72703.26 | O107: =SUM(O8:O105) -> 0 | P107: =SUM(P8:P105) -> 0 | Q107: =SUM(Q8:Q105) -> 0 | R107: =SUM(R8:R105) -> 0 | S107: =SUM(S8:S105) -> 0 | T107: =SUM(T8:T105) -> 0 | U107: =SUM(U8:U105) -> 72703.26 | ... AL107: =SUM(AL8:AL105) -> #N/A
AJ109: =+AJ107*2 -> #N/A
X111: =U107+Z107 -> #N/A

Sheet NOM REAL
A2: =NOMINA!A2 -> NOMINA GENERAL
A5: N° | B5: NOMBRE | C5: CLAVE | D5: TOTAL DEPOSITO | E5: DIAS | F5: SALARIO DIARIO | G5: SUELDO | H5: ART 113 | I5: SUBSIDIO | J5: SUBSIDIO AL EMPLEO | K5: ISR | L5: EMPRESA | M5: FPS | N5: COSTO SOCIAL
A7: 1 | B7: =NOMINA!B7 -> Empleado 1 | C7: =NOMINA!C7 -> Emp 001 | D7: =+NOMINA!D7 -> 0 | E7: 30 | F7: =D7/E7 -> 0 | G7: =+E7*F7 -> 0 | H7: =(G7-VLOOKUP(G7,TABLAS!$A$7:$D$14,1))*VLOOKUP(G7,TABLAS!$A$7:$D$14,4)+VLOOKUP(G7,TABLAS!$A$7:$D$14,3) -> #N/A | I7: =+VLOOKUP(G7,TABLAS!#REF!,3) -> #REF! | J7: =+IF(I7>H7,I7-H7,0) -> #REF! | K7: =+IF(H7>I7,H7-I7,0) -> #N/A | L7: =+G7+J7-K7 -> #REF! | M7: =+IF(K7>0,(D7-G7-#REF!),D7-L7) -> #N/A | N7: ='IMSS REAL'!AL7 -> #N/A
A8: =A7+1 -> 2 | B8: =NOMINA!B8 -> Empleado 2 | C8: =NOMINA!C8 -> Emp 002 | D8: =+NOMINA!D8 -> 0 | E8: 30 | F8: =D8/E8 -> 0 | G8: =+E8*F8 -> 0 | H8: =(G8-VLOOKUP(G8,TABLAS!$A$7:$D$14,1))*VLOOKUP(G8,TABLAS!$A$7:$D$14,4)+VLOOKUP(G8,TABLAS!$A$7:$D$14,3) -> #N/A | I8: =+VLOOKUP(G8,TABLAS!#REF!,3) -> #REF! | J8: =+IF(I8>H8,I8-H8,0) -> #REF! | K8: =+IF(H8>I8,H8-I8,0) -> #N/A | L8: =+G8+J8-K8 -> #REF! | M8: =+IF(K8>0,(D8-G8-#REF!),D8-L8) -> #N/A | N8: ='IMSS REAL'!AL8 -> #N/A
A9: =A8+1 -> 3 | B9: =NOMINA!B9 -> Empleado 3 | C9: =NOMINA!C9 -> Emp 003 | D9: =+NOMINA!D9 -> 0 | E9: 30 | F9: =D9/E9 -> 0 | G9: =+E9*F9 -> 0 | H9: =(G9-VLOOKUP(G9,TABLAS!$A$7:$D$14,1))*VLOOKUP(G9,TABLAS!$A$7:$D$14,4)+VLOOKUP(G9,TABLAS!$A$7:$D$14,3) -> #N/A | I9: =+VLOOKUP(G9,TABLAS!#REF!,3) -> #REF! | J9: =+IF(I9>H9,I9-H9,0) -> #REF! | K9: =+IF(H9>I9,H9-I9,0) -> #N/A | L9: =+G9+J9-K9 -> #REF! | M9: =+IF(K9>0,(D9-G9-#REF!),D9-L9) -> #N/A | N9: ='IMSS REAL'!AL9 -> #N/A
A10: =A9+1 -> 4 | B10: =NOMINA!B10 -> Empleado 4 | C10: =NOMINA!C10 -> Emp 004 | D10: =+NOMINA!D10 -> 0 | E10: 30 | F10: =D10/E10 -> 0 | G10: =+E10*F10 -> 0 | H10: =(G10-VLOOKUP(G10,TABLAS!$A$7:$D$14,1))*VLOOKUP(G10,TABLAS!$A$7:$D$14,4)+VLOOKUP(G10,TABLAS!$A$7:$D$14,3) -> #N/A | I10: =+VLOOKUP(G10,TABLAS!#REF!,3) -> #REF! | J10: =+IF(I10>H10,I10-H10,0) -> #REF! | K10: =+IF(H10>I10,H10-I10,0) -> #N/A | L10: =+G10+J10-K10 -> #REF! | M10: =+IF(K10>0,(D10-G10-#REF!),D10-L10) -> #N/A | N10: ='IMSS REAL'!AL10 -> #N/A
A11: =A10+1 -> 5 | B11: =NOMINA!B11 -> Empleado 5 | C11: =NOMINA!C11 -> Emp 005 | D11: =+NOMINA!D11 -> 0 | E11: 30 | F11: =D11/E11 -> 0 | G11: =+E11*F11 -> 0 | H11: =(G11-VLOOKUP(G11,TABLAS!$A$7:$D$14,1))*VLOOKUP(G11,TABLAS!$A$7:$D$14,4)+VLOOKUP(G11,TABLAS!$A$7:$D$14,3) -> #N/A | I11: =+VLOOKUP(G11,TABLAS!#REF!,3) -> #REF! | J11: =+IF(I11>H11,I11-H11,0) -> #REF! | K11: =+IF(H11>I11,H11-I11,0) -> #N/A | L11: =+G11+J11-K11 -> #REF! | M11: =+IF(K11>0,(D11-G11-#REF!),D11-L11) -> #N/A | N11: ='IMSS REAL'!AL11 -> #N/A
A12: =A11+1 -> 6 | B12: =NOMINA!B12 -> Empleado 6 | C12: =NOMINA!C12 -> Emp 006 | D12: =+NOMINA!D12 -> 0 | E12: 30 | F12: =D12/E12 -> 0 | G12: =+E12*F12 -> 0 | H12: =(G12-VLOOKUP(G12,TABLAS!$A$7:$D$14,1))*VLOOKUP(G12,TABLAS!$A$7:$D$14,4)+VLOOKUP(G12,TABLAS!$A$7:$D$14,3) -> #N/A | I12: =+VLOOKUP(G12,TABLAS!#REF!,3) -> #REF! | J12: =+IF(I12>H12,I12-H12,0) -> #REF! | K12: =+IF(H12>I12,H12-I12,0) -> #N/A | L12: =+G12+J12-K12 -> #REF! | M12: =+IF(K12>0,(D12-G12-#REF!),D12-L12) -> #N/A | N12: ='IMSS REAL'!AL12 -> #N/A
A13: =A12+1 -> 7 | B13: =NOMINA!B13 -> Empleado 7 | C13: =NOMINA!C13 -> Emp 007 | D13: =+NOMINA!D13 -> 0 | E13: 30 | F13: =D13/E13 -> 0 | G13: =+E13*F13 -> 0 | H13: =(G13-VLOOKUP(G13,TABLAS!$A$7:$D$14,1))*VLOOKUP(G13,TABLAS!$A$7:$D$14,4)+VLOOKUP(G13,TABLAS!$A$7:$D$14,3) -> #N/A | I13: =+VLOOKUP(G13,TABLAS!#REF!,3) -> #REF! | J13: =+IF(I13>H13,I13-H13,0) -> #REF! | K13: =+IF(H13>I13,H13-I13,0) -> #N/A | L13: =+G13+J13-K13 -> #REF! | M13: =+IF(K13>0,(D13-G13-#REF!),D13-L13) -> #N/A | N13: ='IMSS REAL'!AL13 -> #N/A
A14: =A13+1 -> 8 | B14: =NOMINA!B14 -> Empleado 8 | C14: =NOMINA!C14 -> Emp 008 | D14: =+NOMINA!D14 -> 0 | E14: 30 | F14: =D14/E14 -> 0 | G14: =+E14*F14 -> 0 | H14: =(G14-VLOOKUP(G14,TABLAS!$A$7:$D$14,1))*VLOOKUP(G14,TABLAS!$A$7:$D$14,4)+VLOOKUP(G14,TABLAS!$A$7:$D$14,3) -> #N/A | I14: =+VLOOKUP(G14,TABLAS!#REF!,3) -> #REF! | J14: =+IF(I14>H14,I14-H14,0) -> #REF! | K14: =+IF(H14>I14,H14-I14,0) -> #N/A | L14: =+G14+J14-K14 -> #REF! | M14: =+IF(K14>0,(D14-G14-#REF!),D14-L14) -> #N/A | N14: ='IMSS REAL'!AL14 -> #N/A
A15: =A14+1 -> 9 | B15: =NOMINA!B15 -> Empleado 9 | C15: =NOMINA!C15 -> Emp 009 | D15: =+NOMINA!D15 -> 0 | E15: 30 | F15: =D15/E15 -> 0 | G15: =+E15*F15 -> 0 | H15: =(G15-VLOOKUP(G15,TABLAS!$A$7:$D$14,1))*VLOOKUP(G15,TABLAS!$A$7:$D$14,4)+VLOOKUP(G15,TABLAS!$A$7:$D$14,3) -> #N/A | I15: =+VLOOKUP(G15,TABLAS!#REF!,3) -> #REF! | J15: =+IF(I15>H15,I15-H15,0) -> #REF! | K15: =+IF(H15>I15,H15-I15,0) -> #N/A | L15: =+G15+J15-K15 -> #REF! | M15: =+IF(K15>0,(D15-G15-#REF!),D15-L15) -> #N/A | N15: ='IMSS REAL'!AL15 -> #N/A
A16: =A15+1 -> 10 | B16: =NOMINA!B16 -> Empleado 10 | C16: =NOMINA!C16 -> Emp 010 | D16: =+NOMINA!D16 -> 0 | E16: 30 | F16: =D16/E16 -> 0 | G16: =+E16*F16 -> 0 | H16: =(G16-VLOOKUP(G16,TABLAS!$A$7:$D$14,1))*VLOOKUP(G16,TABLAS!$A$7:$D$14,4)+VLOOKUP(G16,TABLAS!$A$7:$D$14,3) -> #N/A | I16: =+VLOOKUP(G16,TABLAS!#REF!,3) -> #REF! | J16: =+IF(I16>H16,I16-H16,0) -> #REF! | K16: =+IF(H16>I16,H16-I16,0) -> #N/A | L16: =+G16+J16-K16 -> #REF! | M16: =+IF(K16>0,(D16-G16-#REF!),D16-L16) -> #N/A | N16: ='IMSS REAL'!AL16 -> #N/A
A17: =A16+1 -> 11 | B17: =NOMINA!B17 -> Empleado 11 | C17: =NOMINA!C17 -> Emp 011 | D17: =+NOMINA!D17 -> 0 | E17: 30 | F17: =D17/E17 -> 0 | G17: =+E17*F17 -> 0 | H17: =(G17-VLOOKUP(G17,TABLAS!$A$7:$D$14,1))*VLOOKUP(G17,TABLAS!$A$7:$D$14,4)+VLOOKUP(G17,TABLAS!$A$7:$D$14,3) -> #N/A | I17: =+VLOOKUP(G17,TABLAS!#REF!,3) -> #REF! | J17: =+IF(I17>H17,I17-H17,0) -> #REF! | K17: =+IF(H17>I17,H17-I17,0) -> #N/A | L17: =+G17+J17-K17 -> #REF! | M17: =+IF(K17>0,(D17-G17-#REF!),D17-L17) -> #N/A | N17: ='IMSS REAL'!AL17 -> #N/A
A18: =A17+1 -> 12 | B18: =NOMINA!B18 -> Empleado 12 | C18: =NOMINA!C18 -> Emp 012 | D18: =+NOMINA!D18 -> 0 | E18: 30 | F18: =D18/E18 -> 0 | G18: =+E18*F18 -> 0 | H18: =(G18-VLOOKUP(G18,TABLAS!$A$7:$D$14,1))*VLOOKUP(G18,TABLAS!$A$7:$D$14,4)+VLOOKUP(G18,TABLAS!$A$7:$D$14,3) -> #N/A | I18: =+VLOOKUP(G18,TABLAS!#REF!,3) -> #REF! | J18: =+IF(I18>H18,I18-H18,0) -> #REF! | K18: =+IF(H18>I18,H18-I18,0) -> #N/A | L18: =+G18+J18-K18 -> #REF! | M18: =+IF(K18>0,(D18-G18-#REF!),D18-L18) -> #N/A | N18: ='IMSS REAL'!AL18 -> #N/A
A19: =A18+1 -> 13 | B19: =NOMINA!B19 -> Empleado 13 | C19: =NOMINA!C19 -> Emp 013 | D19: =+NOMINA!D19 -> 0 | E19: 30 | F19: =D19/E19 -> 0 | G19: =+E19*F19 -> 0 | H19: =(G19-VLOOKUP(G19,TABLAS!$A$7:$D$14,1))*VLOOKUP(G19,TABLAS!$A$7:$D$14,4)+VLOOKUP(G19,TABLAS!$A$7:$D$14,3) -> #N/A | I19: =+VLOOKUP(G19,TABLAS!#REF!,3) -> #REF! | J19: =+IF(I19>H19,I19-H19,0) -> #REF! | K19: =+IF(H19>I19,H19-I19,0) -> #N/A | L19: =+G19+J19-K19 -> #REF! | M19: =+IF(K19>0,(D19-G19-#REF!),D19-L19) -> #N/A | N19: ='IMSS REAL'!AL19 -> #N/A
... A104: =A103+1 -> 98 | B104: =NOMINA!B104 -> Empleado 98 | C104: =NOMINA!C104 -> Emp 098 | D104: =+NOMINA!D104 -> 0 | E104: 30 | F104: =D104/E104 -> 0 | G104: =+E104*F104 -> 0 | H104: =(G104-VLOOKUP(G104,TABLAS!$A$7:$D$14,1))*VLOOKUP(G104,TABLAS!$A$7:$D$14,4)+VLOOKUP(G104,TABLAS!$A$7:$D$14,3) -> #N/A | I104: =+VLOOKUP(G104,TABLAS!#REF!,3) -> #REF! | J104: =+IF(I104>H104,I104-H104,0) -> #REF! | K104: =+IF(H104>I104,H104-I104,0) -> #N/A | L104: =+G104+J104-K104 -> #REF! | M104: =+IF(K104>0,(D104-G104-#REF!),D104-L104) -> #N/A | N104: ='IMSS REAL'!AL104 -> #N/A
N106: =SUM(N7:N104) -> #N/A

Sheet IMSS REAL
L1: SMGDF | M1: 3 SMGDF
L2: 117.31 | M2: =+L2*3 -> 351.93 | R2: =+H7*M7 -> 0 | S2: 1
R3: =+R7 -> 0 | S3: 0.053344
N4: ENFERMEDADES Y MATERNIDAD | AB4: COSTO SOCIAL | AG4: INGRESO | AJ4: UITILIDAD
A5: N° | F5: NOMBRE | G5: CLAVE | H5: DIAS | I5: DIAS COTIZADOS | J5: DIAS INCAPACIDAD | K5: DIAS AUSENTISMO | L5: SALARIO DIARIO | M5: SBC | N5: CUOTA FIJA | O5: EXCEDENTE | P5: PREST EN DINERO | Q5: PREST EN ESPECIE | R5: RIESGO DE TRAB | S5: INVALIDEZ Y VIDA | T5: GUARDERIAS | U5: TOTAL IMSS MENSUAL | W5: RETIRO | X5: CESANTIA Y VEJEZ | Y5: INFONAVIT | Z5: TOTAL BIMESTRAL | AB5: TOTAL MENSUAL | AC5: TOTAL RCV E INF | AD5: 4% NOMINA | AE5: TOTAL COSTO | AG5: INGRESO | AH5: IVA | AI5: TOTAL INGRESO | AL5: COSTO POR PERIODO | AM5: COSTO POR DIA
N6: 0.204 | O6: 0.015 | P6: 0.0095 | Q6: 0.01425 | R6: 0.005 | S6: 0.02375 | T6: 0.01 | W6: 0.02 | Y6: 0.05
A7: 1 | F7: ='NOM REAL'!B7 -> Empleado 1 | G7: =NOMINA!C7 -> Emp 001 | H7: =+I7-J7-K7 -> 31 | I7: 31 | J7: 0 | K7: 0 | L7: ='NOM REAL'!F7 -> 0 | M7: =IF(L7*1.0493>$L$2*25,$L$2*25,L7*1.0493) -> 0 | N7: =+ROUND($L$2*$N$6*I7,2) -> 741.87 | O7: =+IF(M7>$M$2,M7-$M$2,0)*$O$6*I7 -> 0 | P7: =+ROUND(M7*$P$6*I7,2) -> 0 | Q7: =+ROUND(M7*$Q$6*I7,2) -> 0 | R7: =+ROUND(M7*$R$6*I7,2) -> 0 | S7: =+ROUND(M7*$S$6*I7,2) -> 0 | T7: =+ROUND(M7*$T$6*I7,2) -> 0 | U7: =+SUM(N7:T7) -> 741.87 | W7: =+ROUND(I7*M7*$W$6,2) -> 0 | X7: =+ROUND(H7*M7*(VLOOKUP(M7,TABLAS!$B$29:$D$35,3,1)+1.125%),2) -> #N/A | Y7: =+ROUND(H7*M7*$Y$6,2) -> 0 | Z7: =+SUM(W7:Y7) -> #N/A | AB7: =+U7 -> 741.87 | AC7: =+Z7 -> #N/A | AD7: =+H7*L7*4% -> 0 | AE7: =+SUM(AB7:AD7) -> #N/A | AG7: =+AE7+AJ7 -> #N/A | AH7: =+AG7*16% -> #N/A | AI7: =+AG7+AH7 -> #N/A | AJ7: =+AE7*7.21% -> #N/A | AK7: =+AG7/2 -> #N/A | AL7: =AM7*'NOM REAL'!E7 -> #N/A | AM7: =AE7/30.4 -> #N/A
A8: =A7+1 -> 2 | F8: ='NOM REAL'!B8 -> Empleado 2 | G8: =NOMINA!C8 -> Emp 002 | H8: =+I8-J8-K8 -> 31 | I8: 31 | J8: 0 | K8: 0 | L8: ='NOM REAL'!F8 -> 0 | M8: =IF(L8*1.0493>$L$2*25,$L$2*25,L8*1.0493) -> 0 | N8: =+ROUND($L$2*$N$6*I8,2) -> 741.87 | O8: =+IF(M8>$M$2,M8-$M$2,0)*$O$6*I8 -> 0 | P8: =+ROUND(M8*$P$6*I8,2) -> 0 | Q8: =+ROUND(M8*$Q$6*I8,2) -> 0 | R8: =+ROUND(M8*$R$6*I8,2) -> 0 | S8: =+ROUND(M8*$S$6*I8,2) -> 0 | T8: =+ROUND(M8*$T$6*I8,2) -> 0 | U8: =+SUM(N8:T8) -> 741.87 | W8: =+ROUND(I8*M8*$W$6,2) -> 0 | X8: =+ROUND(H8*M8*(VLOOKUP(M8,TABLAS!$B$29:$D$35,3,1)+1.125%),2) -> #N/A | Y8: =+ROUND(H8*M8*$Y$6,2) -> 0 | Z8: =+SUM(W8:Y8) -> #N/A | AB8: =+U8 -> 741.87 | AC8: =+Z8 -> #N/A | AD8: =+H8*L8*4% -> 0 | AE8: =+SUM(AB8:AD8) -> #N/A | AG8: =+AE8+AJ8 -> #N/A | AH8: =+AG8*16% -> #N/A | AI8: =+AG8+AH8 -> #N/A | AJ8: =+AE8*7.21% -> #N/A | AK8: =+AG8/2 -> #N/A | AL8: =AM8*'NOM REAL'!E8 -> #N/A | AM8: =AE8/30.4 -> #N/A
A9: =A8+1 -> 3 | F9: ='NOM REAL'!B9 -> Empleado 3 | G9: =NOMINA!C9 -> Emp 003 | H9: =+I9-J9-K9 -> 31 | I9: 31 | J9: 0 | K9: 0 | L9: ='NOM REAL'!F9 -> 0 | M9: =IF(L9*1.0493>$L$2*25,$L$2*25,L9*1.0493) -> 0 | N9: =+ROUND($L$2*$N$6*I9,2) -> 741.87 | O9: =+IF(M9>$M$2,M9-$M$2,0)*$O$6*I9 -> 0 | P9: =+ROUND(M9*$P$6*I9,2) -> 0 | Q9: =+ROUND(M9*$Q$6*I9,2) -> 0 | R9: =+ROUND(M9*$R$6*I9,2) -> 0 | S9: =+ROUND(M9*$S$6*I9,2) -> 0 | T9: =+ROUND(M9*$T$6*I9,2) -> 0 | U9: =+SUM(N9:T9) -> 741.87 | W9: =+ROUND(I9*M9*$W$6,2) -> 0 | X9: =+ROUND(H9*M9*(VLOOKUP(M9,TABLAS!$B$29:$D$35,3,1)+1.125%),2) -> #N/A | Y9: =+ROUND(H9*M9*$Y$6,2) -> 0 | Z9: =+SUM(W9:Y9) -> #N/A | AB9: =+U9 -> 741.87 | AC9: =+Z9 -> #N/A | AD9: =+H9*L9*4% -> 0 | AE9: =+SUM(AB9:AD9) -> #N/A | AG9: =+AE9+AJ9 -> #N/A | AH9: =+AG9*16% -> #N/A | AI9: =+AG9+AH9 -> #N/A | AJ9: =+AE9*7.21% -> #N/A | AK9: =+AG9/2 -> #N/A | AL9: =AM9*'NOM REAL'!E9 -> #N/A | AM9: =AE9/30.4 -> #N/A
A10: =A9+1 -> 4 | F10: ='NOM REAL'!B10 -> Empleado 4 | G10: =NOMINA!C10 -> Emp 004 | H10: =+I10-J10-K10 -> 31 | I10: 31 | J10: 0 | K10: 0 | L10: ='NOM REAL'!F10 -> 0 | M10: =IF(L10*1.0493>$L$2*25,$L$2*25,L10*1.0493) -> 0 | N10: =+ROUND($L$2*$N$6*I10,2) -> 741.87 | O10: =+IF(M10>$M$2,M10-$M$2,0)*$O$6*I10 -> 0 | P10: =+ROUND(M10*$P$6*I10,2) -> 0 | Q10: =+ROUND(M10*$Q$6*I10,2) -> 0 | R10: =+ROUND(M10*$R$6*I10,2) -> 0 | S10: =+ROUND(M10*$S$6*I10,2) -> 0 | T10: =+ROUND(M10*$T$6*I10,2) -> 0 | U10: =+SUM(N10:T10) -> 741.87 | W10: =+ROUND(I10*M10*$W$6,2) -> 0 | X10: =+ROUND(H10*M10*(VLOOKUP(M10,TABLAS!$B$29:$D$35,3,1)+1.125%),2) -> #N/A | Y10: =+ROUND(H10*M10*$Y$6,2) -> 0 | Z10: =+SUM(W10:Y10) -> #N/A | AB10: =+U10 -> 741.87 | AC10: =+Z10 -> #N/A | AD10: =+H10*L10*4% -> 0 | AE10: =+SUM(AB10:AD10) -> #N/A | AG10: =+AE10+AJ10 -> #N/A | AH10: =+AG10*16% -> #N/A | AI10: =+AG10+AH10 -> #N/A | AJ10: =+AE10*7.21% -> #N/A | AK10: =+AG10/2 -> #N/A | AL10: =AM10*'NOM REAL'!E10 -> #N/A | AM10: =AE10/30.4 -> #N/A
A11: =A10+1 -> 5 | F11: ='NOM REAL'!B11 -> Empleado 5 | G11: =NOMINA!C11 -> Emp 005 | H11: =+I11-J11-K11 -> 31 | I11: 31 | J11: 0 | K11: 0 | L11: ='NOM REAL'!F11 -> 0 | M11: =IF(L11*1.0493>$L$2*25,$L$2*25,L11*1.0493) -> 0 | N11: =+ROUND($L$2*$N$6*I11,2) -> 741.87 | O11: =+IF(M11>$M$2,M11-$M$2,0)*$O$6*I11 -> 0 | P11: =+ROUND(M11*$P$6*I11,2) -> 0 | Q11: =+ROUND(M11*$Q$6*I11,2) -> 0 | R11: =+ROUND(M11*$R$6*I11,2) -> 0 | S11: =+ROUND(M11*$S$6*I11,2) -> 0 | T11: =+ROUND(M11*$T$6*I11,2) -> 0 | U11: =+SUM(N11:T11) -> 741.87 | W11: =+ROUND(I11*M11*$W$6,2) -> 0 | X11: =+ROUND(H11*M11*(VLOOKUP(M11,TABLAS!$B$29:$D$35,3,1)+1.125%),2) -> #N/A | Y11: =+ROUND(H11*M11*$Y$6,2) -> 0 | Z11: =+SUM(W11:Y11) -> #N/A | AB11: =+U11 -> 741.87 | AC11: =+Z11 -> #N/A | AD11: =+H11*L11*4% -> 0 | AE11: =+SUM(AB11:AD11) -> #N/A | AG11: =+AE11+AJ11 -> #N/A | AH11: =+AG11*16% -> #N/A | AI11: =+AG11+AH11 -> #N/A | AJ11: =+AE11*7.21% -> #N/A | AK11: =+AG11/2 -> #N/A | AL11: =AM11*'NOM REAL'!E11 -> #N/A | AM11: =AE11/30.4 -> #N/A
A12: =A11+1 -> 6 | F12: ='NOM REAL'!B12 -> Empleado 6 | G12: =NOMINA!C12 -> Emp 006 | H12: =+I12-J12-K12 -> 31 | I12: 31 | J12: 0 | K12: 0 | L12: ='NOM REAL'!F12 -> 0 | M12: =IF(L12*1.0493>$L$2*25,$L$2*25,L12*1.0493) -> 0 | N12: =+ROUND($L$2*$N$6*I12,2) -> 741.87 | O12: =+IF(M12>$M$2,M12-$M$2,0)*$O$6*I12 -> 0 | P12: =+ROUND(M12*$P$6*I12,2) -> 0 | Q12: =+ROUND(M12*$Q$6*I12,2) -> 0 | R12: =+ROUND(M12*$R$6*I12,2) -> 0 | S12: =+ROUND(M12*$S$6*I12,2) -> 0 | T12: =+ROUND(M12*$T$6*I12,2) -> 0 | U12: =+SUM(N12:T12) -> 741.87 | W12: =+ROUND(I12*M12*$W$6,2) -> 0 | X12: =+ROUND(H12*M12*(VLOOKUP(M12,TABLAS!$B$29:$D$35,3,1)+1.125%),2) -> #N/A | Y12: =+ROUND(H12*M12*$Y$6,2) -> 0 | Z12: =+SUM(W12:Y12) -> #N/A | AB12: =+U12 -> 741.87 | AC12: =+Z12 -> #N/A | AD12: =+H12*L12*4% -> 0 | AE12: =+SUM(AB12:AD12) -> #N/A | AG12: =+AE12+AJ12 -> #N/A | AH12: =+AG12*16% -> #N/A | AI12: =+AG12+AH12 -> #N/A | AJ12: =+AE12*7.21% -> #N/A | AK12: =+AG12/2 -> #N/A | AL12: =AM12*'NOM REAL'!E12 -> #N/A | AM12: =AE12/30.4 -> #N/A
A13: =A12+1 -> 7 | F13: ='NOM REAL'!B13 -> Empleado 7 | G13: =NOMINA!C13 -> Emp 007 | H13: =+I13-J13-K13 -> 31 | I13: 31 | J13: 0 | K13: 0 | L13: ='NOM REAL'!F13 -> 0 | M13: =IF(L13*1.0493>$L$2*25,$L$2*25,L13*1.0493) -> 0 | N13: =+ROUND($L$2*$N$6*I13,2) -> 741.87 | O13: =+IF(M13>$M$2,M13-$M$2,0)*$O$6*I13 -> 0 | P13: =+ROUND(M13*$P$6*I13,2) -> 0 | Q13: =+ROUND(M13*$Q$6*I13,2) -> 0 | R13: =+ROUND(M13*$R$6*I13,2) -> 0 | S13: =+ROUND(M13*$S$6*I13,2) -> 0 | T13: =+ROUND(M13*$T$6*I13,2) -> 0 | U13: =+SUM(N13:T13) -> 741.87 | W13: =+ROUND(I13*M13*$W$6,2) -> 0 | X13: =+ROUND(H13*M13*(VLOOKUP(M13,TABLAS!$B$29:$D$35,3,1)+1.125%),2) -> #N/A | Y13: =+ROUND(H13*M13*$Y$6,2) -> 0 | Z13: =+SUM(W13:Y13) -> #N/A | AB13: =+U13 -> 741.87 | AC13: =+Z13 -> #N/A | AD13: =+H13*L13*4% -> 0 | AE13: =+SUM(AB13:AD13) -> #N/A | AG13: =+AE13+AJ13 -> #N/A | AH13: =+AG13*16% -> #N/A | AI13: =+AG13+AH13 -> #N/A | AJ13: =+AE13*7.21% -> #N/A | AK13: =+AG13/2 -> #N/A | AL13: =AM13*'NOM REAL'!E13 -> #N/A | AM13: =AE13/30.4 -> #N/A
A14: =A13+1 -> 8 | F14: ='NOM REAL'!B14 -> Empleado 8 | G14: =NOMINA!C14 -> Emp 008 | H14: =+I14-J14-K14 -> 31 | I14: 31 | J14: 0 | K14: 0 | L14: ='NOM REAL'!F14 -> 0 | M14: =IF(L14*1.0493>$L$2*25,$L$2*25,L14*1.0493) -> 0 | N14: =+ROUND($L$2*$N$6*I14,2) -> 741.87 | O14: =+IF(M14>$M$2,M14-$M$2,0)*$O$6*I14 -> 0 | P14: =+ROUND(M14*$P$6*I14,2) -> 0 | Q14: =+ROUND(M14*$Q$6*I14,2) -> 0 | R14: =+ROUND(M14*$R$6*I14,2) -> 0 | S14: =+ROUND(M14*$S$6*I14,2) -> 0 | T14: =+ROUND(M14*$T$6*I14,2) -> 0 | U14: =+SUM(N14:T14) -> 741.87 | W14: =+ROUND(I14*M14*$W$6,2) -> 0 | X14: =+ROUND(H14*M14*(VLOOKUP(M14,TABLAS!$B$29:$D$35,3,1)+1.125%),2) -> #N/A | Y14: =+ROUND(H14*M14*$Y$6,2) -> 0 | Z14: =+SUM(W14:Y14) -> #N/A | AB14: =+U14 -> 741.87 | AC14: =+Z14 -> #N/A | AD14: =+H14*L14*4% -> 0 | AE14: =+SUM(AB14:AD14) -> #N/A | AG14: =+AE14+AJ14 -> #N/A | AH14: =+AG14*16% -> #N/A | AI14: =+AG14+AH14 -> #N/A | AJ14: =+AE14*7.21% -> #N/A | AK14: =+AG14/2 -> #N/A | AL14: =AM14*'NOM REAL'!E14 -> #N/A | AM14: =AE14/30.4 -> #N/A
A15: =A14+1 -> 9 | F15: ='NOM REAL'!B15 -> Empleado 9 | G15: =NOMINA!C15 -> Emp 009 | H15: =+I15-J15-K15 -> 31 | I15: 31 | J15: 0 | K15: 0 | L15: ='NOM REAL'!F15 -> 0 | M15: =IF(L15*1.0493>$L$2*25,$L$2*25,L15*1.0493) -> 0 | N15: =+ROUND($L$2*$N$6*I15,2) -> 741.87 | O15: =+IF(M15>$M$2,M15-$M$2,0)*$O$6*I15 -> 0 | P15: =+ROUND(M15*$P$6*I15,2) -> 0 | Q15: =+ROUND(M15*$Q$6*I15,2) -> 0 | R15: =+ROUND(M15*$R$6*I15,2) -> 0 | S15: =+ROUND(M15*$S$6*I15,2) -> 0 | T15: =+ROUND(M15*$T$6*I15,2) -> 0 | U15: =+SUM(N15:T15) -> 741.87 | W15: =+ROUND(I15*M15*$W$6,2) -> 0 | X15: =+ROUND(H15*M15*(VLOOKUP(M15,TABLAS!$B$29:$D$35,3,1)+1.125%),2) -> #N/A | Y15: =+ROUND(H15*M15*$Y$6,2) -> 0 | Z15: =+SUM(W15:Y15) -> #N/A | AB15: =+U15 -> 741.87 | AC15: =+Z15 -> #N/A | AD15: =+H15*L15*4% -> 0 | AE15: =+SUM(AB15:AD15) -> #N/A | AG15: =+AE15+AJ15 -> #N/A | AH15: =+AG15*16% -> #N/A | AI15: =+AG15+AH15 -> #N/A | AJ15: =+AE15*7.21% -> #N/A | AK15: =+AG15/2 -> #N/A | AL15: =AM15*'NOM REAL'!E15 -> #N/A | AM15: =AE15/30.4 -> #N/A
A16: =A15+1 -> 10 | F16: ='NOM REAL'!B16 -> Empleado 10 | G16: =NOMINA!C16 -> Emp 010 | H16: =+I16-J16-K16 -> 31 | I16: 31 | J16: 0 | K16: 0 | L16: ='NOM REAL'!F16 -> 0 | M16: =IF(L16*1.0493>$L$2*25,$L$2*25,L16*1.0493) -> 0 | N16: =+ROUND($L$2*$N$6*I16,2) -> 741.87 | O16: =+IF(M16>$M$2,M16-$M$2,0)*$O$6*I16 -> 0 | P16: =+ROUND(M16*$P$6*I16,2) -> 0 | Q16: =+ROUND(M16*$Q$6*I16,2) -> 0 | R16: =+ROUND(M16*$R$6*I16,2) -> 0 | S16: =+ROUND(M16*$S$6*I16,2) -> 0 | T16: =+ROUND(M16*$T$6*I16,2) -> 0 | U16: =+SUM(N16:T16) -> 741.87 | W16: =+ROUND(I16*M16*$W$6,2) -> 0 | X16: =+ROUND(H16*M16*(VLOOKUP(M16,TABLAS!$B$29:$D$35,3,1)+1.125%),2) -> #N/A | Y16: =+ROUND(H16*M16*$Y$6,2) -> 0 | Z16: =+SUM(W16:Y16) -> #N/A | AB16: =+U16 -> 741.87 | AC16: =+Z16 -> #N/A | AD16: =+H16*L16*4% -> 0 | AE16: =+SUM(AB16:AD16) -> #N/A | AG16: =+AE16+AJ16 -> #N/A | AH16: =+AG16*16% -> #N/A | AI16: =+AG16+AH16 -> #N/A | AJ16: =+AE16*7.21% -> #N/A | AK16: =+AG16/2 -> #N/A | AL16: =AM16*'NOM REAL'!E16 -> #N/A | AM16: =AE16/30.4 -> #N/A
A17: =A16+1 -> 11 | F17: ='NOM REAL'!B17 -> Empleado 11 | G17: =NOMINA!C17 -> Emp 011 | H17: =+I17-J17-K17 -> 31 | I17: 31 | J17: 0 | K17: 0 | L17: ='NOM REAL'!F17 -> 0 | M17: =IF(L17*1.0493>$L$2*25,$L$2*25,L17*1.0493) -> 0 | N17: =+ROUND($L$2*$N$6*I17,2) -> 741.87 | O17: =+IF(M17>$M$2,M17-$M$2,0)*$O$6*I17 -> 0 | P17: =+ROUND(M17*$P$6*I17,2) -> 0 | Q17: =+ROUND(M17*$Q$6*I17,2) -> 0 | R17: =+ROUND(M17*$R$6*I17,2) -> 0 | S17: =+ROUND(M17*$S$6*I17,2) -> 0 | T17: =+ROUND(M17*$T$6*I17,2) -> 0 | U17: =+SUM(N17:T17) -> 741.87 | W17: =+ROUND(I17*M17*$W$6,2) -> 0 | X17: =+ROUND(H17*M17*(VLOOKUP(M17,TABLAS!$B$29:$D$35,3,1)+1.125%),2) -> #N/A | Y17: =+ROUND(H17*M17*$Y$6,2) -> 0 | Z17: =+SUM(W17:Y17) -> #N/A | AB17: =+U17 -> 741.87 | AC17: =+Z17 -> #N/A | AD17: =+H17*L17*4% -> 0 | AE17: =+SUM(AB17:AD17) -> #N/A | AG17: =+AE17+AJ17 -> #N/A | AH17: =+AG17*16% -> #N/A | AI17: =+AG17+AH17 -> #N/A | AJ17: =+AE17*7.21% -> #N/A | AK17: =+AG17/2 -> #N/A | AL17: =AM17*'NOM REAL'!E17 -> #N/A | AM17: =AE17/30.4 -> #N/A
A18: =A17+1 -> 12 | F18: ='NOM REAL'!B18 -> Empleado 12 | G18: =NOMINA!C18 -> Emp 012 | H18: =+I18-J18-K18 -> 31 | I18: 31 | J18: 0 | K18: 0 | L18: ='NOM REAL'!F18 -> 0 | M18: =IF(L18*1.0493>$L$2*25,$L$2*25,L18*1.0493) -> 0 | N18: =+ROUND($L$2*$N$6*I18,2) -> 741.87 | O18: =+IF(M18>$M$2,M18-$M$2,0)*$O$6*I18 -> 0 | P18: =+ROUND(M18*$P$6*I18,2) -> 0 | Q18: =+ROUND(M18*$Q$6*I18,2) -> 0 | R18: =+ROUND(M18*$R$6*I18,2) -> 0 | S18: =+ROUND(M18*$S$6*I18,2) -> 0 | T18: =+ROUND(M18*$T$6*I18,2) -> 0 | U18: =+SUM(N18:T18) -> 741.87 | W18: =+ROUND(I18*M18*$W$6,2) -> 0 | X18: =+ROUND(H18*M18*(VLOOKUP(M18,TABLAS!$B$29:$D$35,3,1)+1.125%),2) -> #N/A | Y18: =+ROUND(H18*M18*$Y$6,2) -> 0 | Z18: =+SUM(W18:Y18) -> #N/A | AB18: =+U18 -> 741.87 | AC18: =+Z18 -> #N/A | AD18: =+H18*L18*4% -> 0 | AE18: =+SUM(AB18:AD18) -> #N/A | AG18: =+AE18+AJ18 -> #N/A | AH18: =+AG18*16% -> #N/A | AI18: =+AG18+AH18 -> #N/A | AJ18: =+AE18*7.21% -> #N/A | AK18: =+AG18/2 -> #N/A | AL18: =AM18*'NOM REAL'!E18 -> #N/A | AM18: =AE18/30.4 -> #N/A
A19: =A18+1 -> 13 | F19: ='NOM REAL'!B19 -> Empleado 13 | G19: =NOMINA!C19 -> Emp 013 | H19: =+I19-J19-K19 -> 31 | I19: 31 | J19: 0 | K19: 0 | L19: ='NOM REAL'!F19 -> 0 | M19: =IF(L19*1.0493>$L$2*25,$L$2*25,L19*1.0493) -> 0 | N19: =+ROUND($L$2*$N$6*I19,2) -> 741.87 | O19: =+IF(M19>$M$2,M19-$M$2,0)*$O$6*I19 -> 0 | P19: =+ROUND(M19*$P$6*I19,2) -> 0 | Q19: =+ROUND(M19*$Q$6*I19,2) -> 0 | R19: =+ROUND(M19*$R$6*I19,2) -> 0 | S19: =+ROUND(M19*$S$6*I19,2) -> 0 | T19: =+ROUND(M19*$T$6*I19,2) -> 0 | U19: =+SUM(N19:T19) -> 741.87 | W19: =+ROUND(I19*M19*$W$6,2) -> 0 | X19: =+ROUND(H19*M19*(VLOOKUP(M19,TABLAS!$B$29:$D$35,3,1)+1.125%),2) -> #N/A | Y19: =+ROUND(H19*M19*$Y$6,2) -> 0 | Z19: =+SUM(W19:Y19) -> #N/A | AB19: =+U19 -> 741.87 | AC19: =+Z19 -> #N/A | AD19: =+H19*L19*4% -> 0 | AE19: =+SUM(AB19:AD19) -> #N/A | AG19: =+AE19+AJ19 -> #N/A | AH19: =+AG19*16% -> #N/A | AI19: =+AG19+AH19 -> #N/A | AJ19: =+AE19*7.21% -> #N/A | AK19: =+AG19/2 -> #N/A | AL19: =AM19*'NOM REAL'!E19 -> #N/A | AM19: =AE19/30.4 -> #N/A
... A22: =A21+1 -> 16 | F22: ='NOM REAL'!B22 -> Empleado 16 | G22: =NOMINA!C22 -> Emp 016 | H22: =+I22-J22-K22 -> 31 | I22: 31 | J22: 0 | K22: 0 | L22: ='NOM REAL'!F22 -> 0 | M22: =IF(L22*1.0493>$L$2*25,$L$2*25,L22*1.0493) -> 0 | N22: =+ROUND($L$2*$N$6*I22,2) -> 741.87 | O22: =+IF(M22>$M$2,M22-$M$2,0)*$O$6*I22 -> 0 | P22: =+ROUND(M22*$P$6*I22,2) -> 0 | Q22: =+ROUND(M22*$Q$6*I22,2) -> 0 | R22: =+ROUND(M22*$R$6*I22,2) -> 0 | S22: =+ROUND(M22*$S$6*I22,2) -> 0 | T22: =+ROUND(M22*$T$6*I22,2) -> 0 | U22: =+SUM(N22:T22) -> 741.87 | W22: =+ROUND(I22*M22*$W$6,2) -> 0 | X22: =+ROUND(H22*M22*(VLOOKUP(M22,TABLAS!$B$29:$D$35,3,1)+1.125%),2) -> #N/A | Y22: =+ROUND(H22*M22*$Y$6,2) -> 0 | Z22: =+SUM(W22:Y22) -> #N/A | AB22: =+U22 -> 741.87 | AC22: =+Z22 -> #N/A | AD22: =+H22*L22*4% -> 0 | AE22: =+SUM(AB22:AD22) -> #N/A | AG22: =+AE22+AJ22 -> #N/A | AH22: =+AG22*16% -> #N/A | AI22: =+AG22+AH22 -> #N/A | AJ22: =+AE22*7.21% -> #N/A | AK22: =+AG22/2 -> #N/A | AL22: =AM22*'NOM REAL'!E22 -> #N/A | AM22: =AE22/30.4 -> #N/A
A23: =A22+1 -> 17 | F23: ='NOM REAL'!B105 -> 0 | G23: =NOMINA!C23 -> Emp 017 | H23: =+I23-J23-K23 -> 31 | I23: 31 | J23: 0 | K23: 0 | L23: ='NOM REAL'!F105 -> 0 | M23: =IF(L23*1.0493>$L$2*25,$L$2*25,L23*1.0493) -> 0 | N23: =+ROUND($L$2*$N$6*I23,2) -> 741.87 | O23: =+IF(M23>$M$2,M23-$M$2,0)*$O$6*I23 -> 0 | P23: =+ROUND(M23*$P$6*I23,2) -> 0 | Q23: =+ROUND(M23*$Q$6*I23,2) -> 0 | R23: =+ROUND(M23*$R$6*I23,2) -> 0 | S23: =+ROUND(M23*$S$6*I23,2) -> 0 | T23: =+ROUND(M23*$T$6*I23,2) -> 0 | U23: =+SUM(N23:T23) -> 741.87 | W23: =+ROUND(I23*M23*$W$6,2) -> 0 | X23: =+ROUND(H23*M23*(VLOOKUP(M23,TABLAS!$B$29:$D$35,3,1)+1.125%),2) -> #N/A | Y23: =+ROUND(H23*M23*$Y$6,2) -> 0 | Z23: =+SUM(W23:Y23) -> #N/A | AB23: =+U23 -> 741.87 | AC23: =+Z23 -> #N/A | AD23: =+H23*L23*4% -> 0 | AE23: =+SUM(AB23:AD23) -> #N/A | AG23: =+AE23+AJ23 -> #N/A | AH23: =+AG23*16% -> #N/A | AI23: =+AG23+AH23 -> #N/A | AJ23: =+AE23*7.21% -> #N/A | AK23: =+AG23/2 -> #N/A | AL23: =AM23*'NOM REAL'!E105 -> #N/A | AM23: =AE23/30.4 -> #N/A
A24: =A23+1 -> 18 | F24: ='NOM REAL'!B106 -> 0 | G24: =NOMINA!C24 -> Emp 018 | H24: =+I24-J24-K24 -> 31 | I24: 31 | J24: 0 | K24: 0 | L24: ='NOM REAL'!F106 -> 0 | M24: =IF(L24*1.0493>$L$2*25,$L$2*25,L24*1.0493) -> 0 | N24: =+ROUND($L$2*$N$6*I24,2) -> 741.87 | O24: =+IF(M24>$M$2,M24-$M$2,0)*$O$6*I24 -> 0 | P24: =+ROUND(M24*$P$6*I24,2) -> 0 | Q24: =+ROUND(M24*$Q$6*I24,2) -> 0 | R24: =+ROUND(M24*$R$6*I24,2) -> 0 | S24: =+ROUND(M24*$S$6*I24,2) -> 0 | T24: =+ROUND(M24*$T$6*I24,2) -> 0 | U24: =+SUM(N24:T24) -> 741.87 | W24: =+ROUND(I24*M24*$W$6,2) -> 0 | X24: =+ROUND(H24*M24*(VLOOKUP(M24,TABLAS!$B$29:$D$35,3,1)+1.125%),2) -> #N/A | Y24: =+ROUND(H24*M24*$Y$6,2) -> 0 | Z24: =+SUM(W24:Y24) -> #N/A | AB24: =+U24 -> 741.87 | AC24: =+Z24 -> #N/A | AD24: =+H24*L24*4% -> 0 | AE24: =+SUM(AB24:AD24) -> #N/A | AG24: =+AE24+AJ24 -> #N/A | AH24: =+AG24*16% -> #N/A | AI24: =+AG24+AH24 -> #N/A | AJ24: =+AE24*7.21% -> #N/A | AK24: =+AG24/2 -> #N/A | AL24: =AM24*'NOM REAL'!E106 -> #N/A | AM24: =AE24/30.4 -> #N/A
A25: =A24+1 -> 19 | F25: ='NOM REAL'!B107 -> 0 | G25: =NOMINA!C25 -> Emp 019 | H25: =+I25-J25-K25 -> 31 | I25: 31 | J25: 0 | K25: 0 | L25: ='NOM REAL'!F107 -> 0 | M25: =IF(L25*1.0493>$L$2*25,$L$2*25,L25*1.0493) -> 0 | N25: =+ROUND($L$2*$N$6*I25,2) -> 741.87 | O25: =+IF(M25>$M$2,M25-$M$2,0)*$O$6*I25 -> 0 | P25: =+ROUND(M25*$P$6*I25,2) -> 0 | Q25: =+ROUND(M25*$Q$6*I25,2) -> 0 | R25: =+ROUND(M25*$R$6*I25,2) -> 0 | S25: =+ROUND(M25*$S$6*I25,2) -> 0 | T25: =+ROUND(M25*$T$6*I25,2) -> 0 | U25: =+SUM(N25:T25) -> 741.87 | W25: =+ROUND(I25*M25*$W$6,2) -> 0 | X25: =+ROUND(H25*M25*(VLOOKUP(M25,TABLAS!$B$29:$D$35,3,1)+1.125%),2) -> #N/A | Y25: =+ROUND(H25*M25*$Y$6,2) -> 0 | Z25: =+SUM(W25:Y25) -> #N/A | AB25: =+U25 -> 741.87 | AC25: =+Z25 -> #N/A | AD25: =+H25*L25*4% -> 0 | AE25: =+SUM(AB25:AD25) -> #N/A | AG25: =+AE25+AJ25 -> #N/A | AH25: =+AG25*16% -> #N/A | AI25: =+AG25+AH25 -> #N/A | AJ25: =+AE25*7.21% -> #N/A | AK25: =+AG25/2 -> #N/A | AL25: =AM25*'NOM REAL'!E107 -> #N/A | AM25: =AE25/30.4 -> #N/A
A26: =A25+1 -> 20 | F26: ='NOM REAL'!B108 -> 0 | G26: =NOMINA!C26 -> Emp 020 | H26: =+I26-J26-K26 -> 31 | I26: 31 | J26: 0 | K26: 0 | L26: ='NOM REAL'!F108 -> 0 | M26: =IF(L26*1.0493>$L$2*25,$L$2*25,L26*1.0493) -> 0 | N26: =+ROUND($L$2*$N$6*I26,2) -> 741.87 | O26: =+IF(M26>$M$2,M26-$M$2,0)*$O$6*I26 -> 0 | P26: =+ROUND(M26*$P$6*I26,2) -> 0 | Q26: =+ROUND(M26*$Q$6*I26,2) -> 0 | R26: =+ROUND(M26*$R$6*I26,2) -> 0 | S26: =+ROUND(M26*$S$6*I26,2) -> 0 | T26: =+ROUND(M26*$T$6*I26,2) -> 0 | U26: =+SUM(N26:T26) -> 741.87 | W26: =+ROUND(I26*M26*$W$6,2) -> 0 | X26: =+ROUND(H26*M26*(VLOOKUP(M26,TABLAS!$B$29:$D$35,3,1)+1.125%),2) -> #N/A | Y26: =+ROUND(H26*M26*$Y$6,2) -> 0 | Z26: =+SUM(W26:Y26) -> #N/A | AB26: =+U26 -> 741.87 | AC26: =+Z26 -> #N/A | AD26: =+H26*L26*4% -> 0 | AE26: =+SUM(AB26:AD26) -> #N/A | AG26: =+AE26+AJ26 -> #N/A | AH26: =+AG26*16% -> #N/A | AI26: =+AG26+AH26 -> #N/A | AJ26: =+AE26*7.21% -> #N/A | AK26: =+AG26/2 -> #N/A | AL26: =AM26*'NOM REAL'!E108 -> #N/A | AM26: =AE26/30.4 -> #N/A
A27: =A26+1 -> 21 | F27: ='NOM REAL'!B109 -> 0 | G27: =NOMINA!C27 -> Emp 021 | H27: =+I27-J27-K27 -> 31 | I27: 31 | J27: 0 | K27: 0 | L27: ='NOM REAL'!F109 -> 0 | M27: =IF(L27*1.0493>$L$2*25,$L$2*25,L27*1.0493) -> 0 | N27: =+ROUND($L$2*$N$6*I27,2) -> 741.87 | O27: =+IF(M27>$M$2,M27-$M$2,0)*$O$6*I27 -> 0 | P27: =+ROUND(M27*$P$6*I27,2) -> 0 | Q27: =+ROUND(M27*$Q$6*I27,2) -> 0 | R27: =+ROUND(M27*$R$6*I27,2) -> 0 | S27: =+ROUND(M27*$S$6*I27,2) -> 0 | T27: =+ROUND(M27*$T$6*I27,2) -> 0 | U27: =+SUM(N27:T27) -> 741.87 | W27: =+ROUND(I27*M27*$W$6,2) -> 0 | X27: =+ROUND(H27*M27*(VLOOKUP(M27,TABLAS!$B$29:$D$35,3,1)+1.125%),2) -> #N/A | Y27: =+ROUND(H27*M27*$Y$6,2) -> 0 | Z27: =+SUM(W27:Y27) -> #N/A | AB27: =+U27 -> 741.87 | AC27: =+Z27 -> #N/A | AD27: =+H27*L27*4% -> 0 | AE27: =+SUM(AB27:AD27) -> #N/A | AG27: =+AE27+AJ27 -> #N/A | AH27: =+AG27*16% -> #N/A | AI27: =+AG27+AH27 -> #N/A | AJ27: =+AE27*7.21% -> #N/A | AK27: =+AG27/2 -> #N/A | AL27: =AM27*'NOM REAL'!E109 -> #N/A | AM27: =AE27/30.4 -> #N/A
